<?xml version="1.0" ?>
<!-- =================================================================================== -->
<!-- |    This document was autogenerated by xacro from /home/cem/colcon_ws/src/ifarlab_gazebo/urdf/combined_system.urdf.xacro | -->
<!-- |    EDITING THIS FILE BY HAND IS NOT RECOMMENDED                                 | -->
<!-- =================================================================================== -->
<robot name="ifarlab_combined">
  <!-- A universal world link for the static parts of the scene -->
  <link name="world"/>
  <!--
    Base UR robot series xacro macro.

    NOTE this is NOT a URDF. It cannot directly be loaded by consumers
    expecting a flattened '.urdf' file. See the top-level '.xacro' for that
    (but note that .xacro must still be processed by the xacro command).

    This file models the base kinematic chain of a UR robot, which then gets
    parameterised by various configuration files to convert it into a UR3(e),
    UR5(e), UR10(e) or UR16e.

    NOTE the default kinematic parameters (i.e., link lengths, frame locations,
    offsets, etc) do not correspond to any particular robot. They are defaults
    only. There WILL be non-zero offsets between the Forward Kinematics results
    in TF (i.e., robot_state_publisher) and the values reported by the Teach
    Pendant.

    For accurate (and robot-specific) transforms, the 'kinematics_parameters_file'
    parameter MUST point to a .yaml file containing the appropriate values for
    the targeted robot.

    If using the UniversalRobots/Universal_Robots_ROS_Driver, follow the steps
    described in the readme of that repository to extract the kinematic
    calibration from the controller and generate the required .yaml file.

    Main author of the migration to yaml configs Ludovic Delval.

    Contributors to previous versions (in no particular order)

     - Denis Stogl
     - Lovro Ivanov
     - Felix Messmer
     - Kelsey Hawkins
     - Wim Meeussen
     - Shaun Edwards
     - Nadia Hammoudeh Garcia
     - Dave Hershberger
     - G. vd. Hoorn
     - Philip Long
     - Dave Coleman
     - Miguel Prada
     - Mathias Luedtke
     - Marcel Schnirring
     - Felix von Drigalski
     - Felix Exner
     - Jimmy Da Silva
     - Ajit Krisshna N L
     - Muhammad Asif Rana
  -->
  <!--
    NOTE the macro defined in this file is NOT part of the public API of this
          package. Users CANNOT rely on this file being available, or stored in
          this location. Nor can they rely on the existence of the macro.
  -->
  <!-- Renk tanımlamaları -->
  <material name="chassis_red">
    <color rgba="1.0 0.0 0.0 1.0"/>
  </material>
  <material name="chassis_grey">
    <color rgba="0.7 0.7 0.7 1.0"/>
  </material>
  <material name="silver">
    <color rgba="0.8 0.8 0.8 1.0"/>
  </material>
  <link name="sim_ur10e_table">
    <inertial>
      <origin rpy="0 0 0" xyz="-0.11578560444646112 1.1997807817885673 0.4198575454601515"/>
      <mass value="54.501673015936554"/>
      <inertia ixx="28.453985" ixy="-0.075126" ixz="-0.006467" iyy="1.801962" iyz="0.004704" izz="27.627414"/>
    </inertial>
    <visual>
      <origin rpy="0 0 0" xyz="0 0 0"/>
      <geometry>
        <mesh filename="file:////home/cem/colcon_ws/src/Universal_Robots_ROS2_Description/meshes/ur10e/collision/base_link.stl" scale="0.001 0.001 0.001"/>
      </geometry>
      <material name="silver"/>
    </visual>
    <collision>
      <origin rpy="0 0 0" xyz="0 0 0"/>
      <geometry>
        <mesh filename="file:////home/cem/colcon_ws/src/Universal_Robots_ROS2_Description/meshes/ur10e/collision/base_link.stl" scale="0.001 0.001 0.001"/>
      </geometry>
    </collision>
  </link>
  <!-- Ana chassis base link - tüm parçalar buna bağlanacak -->
  <link name="sim_ur10e_chassis">
    <inertial>
      <origin rpy="0 0 0" xyz="-1.124731 1.232845 1.108302"/>
      <mass value="120.90442642947052"/>
      <inertia ixx="129.47263" ixy="-0.023527" ixz="-0.011644" iyy="73.136591" iyz="-1.726202" izz="85.878511"/>
    </inertial>
  </link>
  <!-- Ana chassis'i parent'a bağla -->
  <joint name="sim_ur10e_base_to_chassis" type="fixed">
    <origin rpy="0 0 0" xyz="0 0 0"/>
    <parent link="world"/>
    <child link="sim_ur10e_chassis"/>
  </joint>
  <link name="sim_ur10e_chassis_part1">
    <visual>
      <origin rpy="0 0 0" xyz="0 0 0"/>
      <geometry>
        <mesh filename="file:////home/cem/colcon_ws/src/Universal_Robots_ROS2_Description/meshes/ur10e/collision/chassis/PART1.stl" scale="0.001 0.001 0.001"/>
      </geometry>
      <material name="chassis_grey"/>
    </visual>
    <collision>
      <origin rpy="0 0 0" xyz="0 0 0"/>
      <geometry>
        <mesh filename="file:////home/cem/colcon_ws/src/Universal_Robots_ROS2_Description/meshes/ur10e/collision/chassis/PART1.stl" scale="0.001 0.001 0.001"/>
      </geometry>
    </collision>
    <inertial>
      <origin rpy="0 0 0" xyz="0 0 0"/>
      <mass value="2.75"/>
      <inertia ixx="0.001" ixy="0.0" ixz="0.0" iyy="0.001" iyz="0.0" izz="0.001"/>
    </inertial>
  </link>
  <joint name="sim_ur10e__chassis_to_part1" type="fixed">
    <parent link="sim_ur10e_chassis"/>
    <child link="sim_ur10e_chassis_part1"/>
    <origin rpy="0 0 0" xyz="0 0 0"/>
  </joint>
  <link name="sim_ur10e_chassis_part2">
    <visual>
      <origin rpy="0 0 0" xyz="0 0 0"/>
      <geometry>
        <mesh filename="file:////home/cem/colcon_ws/src/Universal_Robots_ROS2_Description/meshes/ur10e/collision/chassis/PART2.stl" scale="0.001 0.001 0.001"/>
      </geometry>
      <material name="chassis_grey"/>
    </visual>
    <collision>
      <origin rpy="0 0 0" xyz="0 0 0"/>
      <geometry>
        <mesh filename="file:////home/cem/colcon_ws/src/Universal_Robots_ROS2_Description/meshes/ur10e/collision/chassis/PART2.stl" scale="0.001 0.001 0.001"/>
      </geometry>
    </collision>
    <inertial>
      <origin rpy="0 0 0" xyz="0 0 0"/>
      <mass value="2.75"/>
      <inertia ixx="0.001" ixy="0.0" ixz="0.0" iyy="0.001" iyz="0.0" izz="0.001"/>
    </inertial>
  </link>
  <joint name="sim_ur10e__chassis_to_part2" type="fixed">
    <parent link="sim_ur10e_chassis"/>
    <child link="sim_ur10e_chassis_part2"/>
    <origin rpy="0 0 0" xyz="0 0 0"/>
  </joint>
  <link name="sim_ur10e_chassis_part3">
    <visual>
      <origin rpy="0 0 0" xyz="0 0 0"/>
      <geometry>
        <mesh filename="file:////home/cem/colcon_ws/src/Universal_Robots_ROS2_Description/meshes/ur10e/collision/chassis/PART3.stl" scale="0.001 0.001 0.001"/>
      </geometry>
      <material name="chassis_grey"/>
    </visual>
    <collision>
      <origin rpy="0 0 0" xyz="0 0 0"/>
      <geometry>
        <mesh filename="file:////home/cem/colcon_ws/src/Universal_Robots_ROS2_Description/meshes/ur10e/collision/chassis/PART3.stl" scale="0.001 0.001 0.001"/>
      </geometry>
    </collision>
    <inertial>
      <origin rpy="0 0 0" xyz="0 0 0"/>
      <mass value="2.75"/>
      <inertia ixx="0.001" ixy="0.0" ixz="0.0" iyy="0.001" iyz="0.0" izz="0.001"/>
    </inertial>
  </link>
  <joint name="sim_ur10e__chassis_to_part3" type="fixed">
    <parent link="sim_ur10e_chassis"/>
    <child link="sim_ur10e_chassis_part3"/>
    <origin rpy="0 0 0" xyz="0 0 0"/>
  </joint>
  <link name="sim_ur10e_chassis_part4">
    <visual>
      <origin rpy="0 0 0" xyz="0 0 0"/>
      <geometry>
        <mesh filename="file:////home/cem/colcon_ws/src/Universal_Robots_ROS2_Description/meshes/ur10e/collision/chassis/PART4.stl" scale="0.001 0.001 0.001"/>
      </geometry>
      <material name="chassis_grey"/>
    </visual>
    <collision>
      <origin rpy="0 0 0" xyz="0 0 0"/>
      <geometry>
        <mesh filename="file:////home/cem/colcon_ws/src/Universal_Robots_ROS2_Description/meshes/ur10e/collision/chassis/PART4.stl" scale="0.001 0.001 0.001"/>
      </geometry>
    </collision>
    <inertial>
      <origin rpy="0 0 0" xyz="0 0 0"/>
      <mass value="2.75"/>
      <inertia ixx="0.001" ixy="0.0" ixz="0.0" iyy="0.001" iyz="0.0" izz="0.001"/>
    </inertial>
  </link>
  <joint name="sim_ur10e__chassis_to_part4" type="fixed">
    <parent link="sim_ur10e_chassis"/>
    <child link="sim_ur10e_chassis_part4"/>
    <origin rpy="0 0 0" xyz="0 0 0"/>
  </joint>
  <link name="sim_ur10e_chassis_part5">
    <visual>
      <origin rpy="0 0 0" xyz="0 0 0"/>
      <geometry>
        <mesh filename="file:////home/cem/colcon_ws/src/Universal_Robots_ROS2_Description/meshes/ur10e/collision/chassis/PART5.stl" scale="0.001 0.001 0.001"/>
      </geometry>
      <material name="chassis_grey"/>
    </visual>
    <collision>
      <origin rpy="0 0 0" xyz="0 0 0"/>
      <geometry>
        <mesh filename="file:////home/cem/colcon_ws/src/Universal_Robots_ROS2_Description/meshes/ur10e/collision/chassis/PART5.stl" scale="0.001 0.001 0.001"/>
      </geometry>
    </collision>
    <inertial>
      <origin rpy="0 0 0" xyz="0 0 0"/>
      <mass value="2.75"/>
      <inertia ixx="0.001" ixy="0.0" ixz="0.0" iyy="0.001" iyz="0.0" izz="0.001"/>
    </inertial>
  </link>
  <joint name="sim_ur10e__chassis_to_part5" type="fixed">
    <parent link="sim_ur10e_chassis"/>
    <child link="sim_ur10e_chassis_part5"/>
    <origin rpy="0 0 0" xyz="0 0 0"/>
  </joint>
  <link name="sim_ur10e_chassis_part6">
    <visual>
      <origin rpy="0 0 0" xyz="0 0 0"/>
      <geometry>
        <mesh filename="file:////home/cem/colcon_ws/src/Universal_Robots_ROS2_Description/meshes/ur10e/collision/chassis/PART6.stl" scale="0.001 0.001 0.001"/>
      </geometry>
      <material name="chassis_grey"/>
    </visual>
    <collision>
      <origin rpy="0 0 0" xyz="0 0 0"/>
      <geometry>
        <mesh filename="file:////home/cem/colcon_ws/src/Universal_Robots_ROS2_Description/meshes/ur10e/collision/chassis/PART6.stl" scale="0.001 0.001 0.001"/>
      </geometry>
    </collision>
    <inertial>
      <origin rpy="0 0 0" xyz="0 0 0"/>
      <mass value="2.75"/>
      <inertia ixx="0.001" ixy="0.0" ixz="0.0" iyy="0.001" iyz="0.0" izz="0.001"/>
    </inertial>
  </link>
  <joint name="sim_ur10e__chassis_to_part6" type="fixed">
    <parent link="sim_ur10e_chassis"/>
    <child link="sim_ur10e_chassis_part6"/>
    <origin rpy="0 0 0" xyz="0 0 0"/>
  </joint>
  <link name="sim_ur10e_chassis_part7">
    <visual>
      <origin rpy="0 0 0" xyz="0 0 0"/>
      <geometry>
        <mesh filename="file:////home/cem/colcon_ws/src/Universal_Robots_ROS2_Description/meshes/ur10e/collision/chassis/PART7.stl" scale="0.001 0.001 0.001"/>
      </geometry>
      <material name="chassis_grey"/>
    </visual>
    <collision>
      <origin rpy="0 0 0" xyz="0 0 0"/>
      <geometry>
        <mesh filename="file:////home/cem/colcon_ws/src/Universal_Robots_ROS2_Description/meshes/ur10e/collision/chassis/PART7.stl" scale="0.001 0.001 0.001"/>
      </geometry>
    </collision>
    <inertial>
      <origin rpy="0 0 0" xyz="0 0 0"/>
      <mass value="2.75"/>
      <inertia ixx="0.001" ixy="0.0" ixz="0.0" iyy="0.001" iyz="0.0" izz="0.001"/>
    </inertial>
  </link>
  <joint name="sim_ur10e__chassis_to_part7" type="fixed">
    <parent link="sim_ur10e_chassis"/>
    <child link="sim_ur10e_chassis_part7"/>
    <origin rpy="0 0 0" xyz="0 0 0"/>
  </joint>
  <link name="sim_ur10e_chassis_part8">
    <visual>
      <origin rpy="0 0 0" xyz="0 0 0"/>
      <geometry>
        <mesh filename="file:////home/cem/colcon_ws/src/Universal_Robots_ROS2_Description/meshes/ur10e/collision/chassis/PART8.stl" scale="0.001 0.001 0.001"/>
      </geometry>
      <material name="chassis_grey"/>
    </visual>
    <collision>
      <origin rpy="0 0 0" xyz="0 0 0"/>
      <geometry>
        <mesh filename="file:////home/cem/colcon_ws/src/Universal_Robots_ROS2_Description/meshes/ur10e/collision/chassis/PART8.stl" scale="0.001 0.001 0.001"/>
      </geometry>
    </collision>
    <inertial>
      <origin rpy="0 0 0" xyz="0 0 0"/>
      <mass value="2.75"/>
      <inertia ixx="0.001" ixy="0.0" ixz="0.0" iyy="0.001" iyz="0.0" izz="0.001"/>
    </inertial>
  </link>
  <joint name="sim_ur10e__chassis_to_part8" type="fixed">
    <parent link="sim_ur10e_chassis"/>
    <child link="sim_ur10e_chassis_part8"/>
    <origin rpy="0 0 0" xyz="0 0 0"/>
  </joint>
  <link name="sim_ur10e_chassis_part9">
    <visual>
      <origin rpy="0 0 0" xyz="0 0 0"/>
      <geometry>
        <mesh filename="file:////home/cem/colcon_ws/src/Universal_Robots_ROS2_Description/meshes/ur10e/collision/chassis/PART9.stl" scale="0.001 0.001 0.001"/>
      </geometry>
      <material name="chassis_grey"/>
    </visual>
    <collision>
      <origin rpy="0 0 0" xyz="0 0 0"/>
      <geometry>
        <mesh filename="file:////home/cem/colcon_ws/src/Universal_Robots_ROS2_Description/meshes/ur10e/collision/chassis/PART9.stl" scale="0.001 0.001 0.001"/>
      </geometry>
    </collision>
    <inertial>
      <origin rpy="0 0 0" xyz="0 0 0"/>
      <mass value="2.75"/>
      <inertia ixx="0.001" ixy="0.0" ixz="0.0" iyy="0.001" iyz="0.0" izz="0.001"/>
    </inertial>
  </link>
  <joint name="sim_ur10e__chassis_to_part9" type="fixed">
    <parent link="sim_ur10e_chassis"/>
    <child link="sim_ur10e_chassis_part9"/>
    <origin rpy="0 0 0" xyz="0 0 0"/>
  </joint>
  <link name="sim_ur10e_chassis_part10">
    <visual>
      <origin rpy="0 0 0" xyz="0 0 0"/>
      <geometry>
        <mesh filename="file:////home/cem/colcon_ws/src/Universal_Robots_ROS2_Description/meshes/ur10e/collision/chassis/PART10.stl" scale="0.001 0.001 0.001"/>
      </geometry>
      <material name="chassis_grey"/>
    </visual>
    <collision>
      <origin rpy="0 0 0" xyz="0 0 0"/>
      <geometry>
        <mesh filename="file:////home/cem/colcon_ws/src/Universal_Robots_ROS2_Description/meshes/ur10e/collision/chassis/PART10.stl" scale="0.001 0.001 0.001"/>
      </geometry>
    </collision>
    <inertial>
      <origin rpy="0 0 0" xyz="0 0 0"/>
      <mass value="2.75"/>
      <inertia ixx="0.001" ixy="0.0" ixz="0.0" iyy="0.001" iyz="0.0" izz="0.001"/>
    </inertial>
  </link>
  <joint name="sim_ur10e__chassis_to_part10" type="fixed">
    <parent link="sim_ur10e_chassis"/>
    <child link="sim_ur10e_chassis_part10"/>
    <origin rpy="0 0 0" xyz="0 0 0"/>
  </joint>
  <link name="sim_ur10e_chassis_part11">
    <visual>
      <origin rpy="0 0 0" xyz="0 0 0"/>
      <geometry>
        <mesh filename="file:////home/cem/colcon_ws/src/Universal_Robots_ROS2_Description/meshes/ur10e/collision/chassis/PART11.stl" scale="0.001 0.001 0.001"/>
      </geometry>
      <material name="chassis_grey"/>
    </visual>
    <collision>
      <origin rpy="0 0 0" xyz="0 0 0"/>
      <geometry>
        <mesh filename="file:////home/cem/colcon_ws/src/Universal_Robots_ROS2_Description/meshes/ur10e/collision/chassis/PART11.stl" scale="0.001 0.001 0.001"/>
      </geometry>
    </collision>
    <inertial>
      <origin rpy="0 0 0" xyz="0 0 0"/>
      <mass value="2.75"/>
      <inertia ixx="0.001" ixy="0.0" ixz="0.0" iyy="0.001" iyz="0.0" izz="0.001"/>
    </inertial>
  </link>
  <joint name="sim_ur10e__chassis_to_part11" type="fixed">
    <parent link="sim_ur10e_chassis"/>
    <child link="sim_ur10e_chassis_part11"/>
    <origin rpy="0 0 0" xyz="0 0 0"/>
  </joint>
  <link name="sim_ur10e_chassis_part12">
    <visual>
      <origin rpy="0 0 0" xyz="0 0 0"/>
      <geometry>
        <mesh filename="file:////home/cem/colcon_ws/src/Universal_Robots_ROS2_Description/meshes/ur10e/collision/chassis/PART12.stl" scale="0.001 0.001 0.001"/>
      </geometry>
      <material name="chassis_grey"/>
    </visual>
    <collision>
      <origin rpy="0 0 0" xyz="0 0 0"/>
      <geometry>
        <mesh filename="file:////home/cem/colcon_ws/src/Universal_Robots_ROS2_Description/meshes/ur10e/collision/chassis/PART12.stl" scale="0.001 0.001 0.001"/>
      </geometry>
    </collision>
    <inertial>
      <origin rpy="0 0 0" xyz="0 0 0"/>
      <mass value="2.75"/>
      <inertia ixx="0.001" ixy="0.0" ixz="0.0" iyy="0.001" iyz="0.0" izz="0.001"/>
    </inertial>
  </link>
  <joint name="sim_ur10e__chassis_to_part12" type="fixed">
    <parent link="sim_ur10e_chassis"/>
    <child link="sim_ur10e_chassis_part12"/>
    <origin rpy="0 0 0" xyz="0 0 0"/>
  </joint>
  <link name="sim_ur10e_chassis_part13">
    <visual>
      <origin rpy="0 0 0" xyz="0 0 0"/>
      <geometry>
        <mesh filename="file:////home/cem/colcon_ws/src/Universal_Robots_ROS2_Description/meshes/ur10e/collision/chassis/PART13.stl" scale="0.001 0.001 0.001"/>
      </geometry>
      <material name="chassis_grey"/>
    </visual>
    <collision>
      <origin rpy="0 0 0" xyz="0 0 0"/>
      <geometry>
        <mesh filename="file:////home/cem/colcon_ws/src/Universal_Robots_ROS2_Description/meshes/ur10e/collision/chassis/PART13.stl" scale="0.001 0.001 0.001"/>
      </geometry>
    </collision>
    <inertial>
      <origin rpy="0 0 0" xyz="0 0 0"/>
      <mass value="2.75"/>
      <inertia ixx="0.001" ixy="0.0" ixz="0.0" iyy="0.001" iyz="0.0" izz="0.001"/>
    </inertial>
  </link>
  <joint name="sim_ur10e__chassis_to_part13" type="fixed">
    <parent link="sim_ur10e_chassis"/>
    <child link="sim_ur10e_chassis_part13"/>
    <origin rpy="0 0 0" xyz="0 0 0"/>
  </joint>
  <link name="sim_ur10e_chassis_part14">
    <visual>
      <origin rpy="0 0 0" xyz="0 0 0"/>
      <geometry>
        <mesh filename="file:////home/cem/colcon_ws/src/Universal_Robots_ROS2_Description/meshes/ur10e/collision/chassis/PART14.stl" scale="0.001 0.001 0.001"/>
      </geometry>
      <material name="chassis_grey"/>
    </visual>
    <collision>
      <origin rpy="0 0 0" xyz="0 0 0"/>
      <geometry>
        <mesh filename="file:////home/cem/colcon_ws/src/Universal_Robots_ROS2_Description/meshes/ur10e/collision/chassis/PART14.stl" scale="0.001 0.001 0.001"/>
      </geometry>
    </collision>
    <inertial>
      <origin rpy="0 0 0" xyz="0 0 0"/>
      <mass value="2.75"/>
      <inertia ixx="0.001" ixy="0.0" ixz="0.0" iyy="0.001" iyz="0.0" izz="0.001"/>
    </inertial>
  </link>
  <joint name="sim_ur10e__chassis_to_part14" type="fixed">
    <parent link="sim_ur10e_chassis"/>
    <child link="sim_ur10e_chassis_part14"/>
    <origin rpy="0 0 0" xyz="0 0 0"/>
  </joint>
  <link name="sim_ur10e_chassis_part15">
    <visual>
      <origin rpy="0 0 0" xyz="0 0 0"/>
      <geometry>
        <mesh filename="file:////home/cem/colcon_ws/src/Universal_Robots_ROS2_Description/meshes/ur10e/collision/chassis/PART15.stl" scale="0.001 0.001 0.001"/>
      </geometry>
      <material name="chassis_grey"/>
    </visual>
    <collision>
      <origin rpy="0 0 0" xyz="0 0 0"/>
      <geometry>
        <mesh filename="file:////home/cem/colcon_ws/src/Universal_Robots_ROS2_Description/meshes/ur10e/collision/chassis/PART15.stl" scale="0.001 0.001 0.001"/>
      </geometry>
    </collision>
    <inertial>
      <origin rpy="0 0 0" xyz="0 0 0"/>
      <mass value="2.75"/>
      <inertia ixx="0.001" ixy="0.0" ixz="0.0" iyy="0.001" iyz="0.0" izz="0.001"/>
    </inertial>
  </link>
  <joint name="sim_ur10e__chassis_to_part15" type="fixed">
    <parent link="sim_ur10e_chassis"/>
    <child link="sim_ur10e_chassis_part15"/>
    <origin rpy="0 0 0" xyz="0 0 0"/>
  </joint>
  <link name="sim_ur10e_chassis_part16">
    <visual>
      <origin rpy="0 0 0" xyz="0 0 0"/>
      <geometry>
        <mesh filename="file:////home/cem/colcon_ws/src/Universal_Robots_ROS2_Description/meshes/ur10e/collision/chassis/PART16.stl" scale="0.001 0.001 0.001"/>
      </geometry>
      <material name="chassis_grey"/>
    </visual>
    <collision>
      <origin rpy="0 0 0" xyz="0 0 0"/>
      <geometry>
        <mesh filename="file:////home/cem/colcon_ws/src/Universal_Robots_ROS2_Description/meshes/ur10e/collision/chassis/PART16.stl" scale="0.001 0.001 0.001"/>
      </geometry>
    </collision>
    <inertial>
      <origin rpy="0 0 0" xyz="0 0 0"/>
      <mass value="2.75"/>
      <inertia ixx="0.001" ixy="0.0" ixz="0.0" iyy="0.001" iyz="0.0" izz="0.001"/>
    </inertial>
  </link>
  <joint name="sim_ur10e__chassis_to_part16" type="fixed">
    <parent link="sim_ur10e_chassis"/>
    <child link="sim_ur10e_chassis_part16"/>
    <origin rpy="0 0 0" xyz="0 0 0"/>
  </joint>
  <link name="sim_ur10e_chassis_part17">
    <visual>
      <origin rpy="0 0 0" xyz="0 0 0"/>
      <geometry>
        <mesh filename="file:////home/cem/colcon_ws/src/Universal_Robots_ROS2_Description/meshes/ur10e/collision/chassis/PART17.stl" scale="0.001 0.001 0.001"/>
      </geometry>
      <material name="chassis_red"/>
    </visual>
    <collision>
      <origin rpy="0 0 0" xyz="0 0 0"/>
      <geometry>
        <mesh filename="file:////home/cem/colcon_ws/src/Universal_Robots_ROS2_Description/meshes/ur10e/collision/chassis/PART17.stl" scale="0.001 0.001 0.001"/>
      </geometry>
    </collision>
    <inertial>
      <origin rpy="0 0 0" xyz="0 0 0"/>
      <mass value="2.75"/>
      <inertia ixx="0.001" ixy="0.0" ixz="0.0" iyy="0.001" iyz="0.0" izz="0.001"/>
    </inertial>
  </link>
  <joint name="sim_ur10e__chassis_to_part17" type="fixed">
    <parent link="sim_ur10e_chassis"/>
    <child link="sim_ur10e_chassis_part17"/>
    <origin rpy="0 0 0" xyz="0 0 0"/>
  </joint>
  <link name="sim_ur10e_chassis_part18">
    <visual>
      <origin rpy="0 0 0" xyz="0 0 0"/>
      <geometry>
        <mesh filename="file:////home/cem/colcon_ws/src/Universal_Robots_ROS2_Description/meshes/ur10e/collision/chassis/PART18.stl" scale="0.001 0.001 0.001"/>
      </geometry>
      <material name="chassis_grey"/>
    </visual>
    <collision>
      <origin rpy="0 0 0" xyz="0 0 0"/>
      <geometry>
        <mesh filename="file:////home/cem/colcon_ws/src/Universal_Robots_ROS2_Description/meshes/ur10e/collision/chassis/PART18.stl" scale="0.001 0.001 0.001"/>
      </geometry>
    </collision>
    <inertial>
      <origin rpy="0 0 0" xyz="0 0 0"/>
      <mass value="2.75"/>
      <inertia ixx="0.001" ixy="0.0" ixz="0.0" iyy="0.001" iyz="0.0" izz="0.001"/>
    </inertial>
  </link>
  <joint name="sim_ur10e__chassis_to_part18" type="fixed">
    <parent link="sim_ur10e_chassis"/>
    <child link="sim_ur10e_chassis_part18"/>
    <origin rpy="0 0 0" xyz="0 0 0"/>
  </joint>
  <link name="sim_ur10e_chassis_part19">
    <visual>
      <origin rpy="0 0 0" xyz="0 0 0"/>
      <geometry>
        <mesh filename="file:////home/cem/colcon_ws/src/Universal_Robots_ROS2_Description/meshes/ur10e/collision/chassis/PART19.stl" scale="0.001 0.001 0.001"/>
      </geometry>
      <material name="chassis_grey"/>
    </visual>
    <collision>
      <origin rpy="0 0 0" xyz="0 0 0"/>
      <geometry>
        <mesh filename="file:////home/cem/colcon_ws/src/Universal_Robots_ROS2_Description/meshes/ur10e/collision/chassis/PART19.stl" scale="0.001 0.001 0.001"/>
      </geometry>
    </collision>
    <inertial>
      <origin rpy="0 0 0" xyz="0 0 0"/>
      <mass value="2.75"/>
      <inertia ixx="0.001" ixy="0.0" ixz="0.0" iyy="0.001" iyz="0.0" izz="0.001"/>
    </inertial>
  </link>
  <joint name="sim_ur10e__chassis_to_part19" type="fixed">
    <parent link="sim_ur10e_chassis"/>
    <child link="sim_ur10e_chassis_part19"/>
    <origin rpy="0 0 0" xyz="0 0 0"/>
  </joint>
  <link name="sim_ur10e_chassis_part20">
    <visual>
      <origin rpy="0 0 0" xyz="0 0 0"/>
      <geometry>
        <mesh filename="file:////home/cem/colcon_ws/src/Universal_Robots_ROS2_Description/meshes/ur10e/collision/chassis/PART20.stl" scale="0.001 0.001 0.001"/>
      </geometry>
      <material name="chassis_grey"/>
    </visual>
    <collision>
      <origin rpy="0 0 0" xyz="0 0 0"/>
      <geometry>
        <mesh filename="file:////home/cem/colcon_ws/src/Universal_Robots_ROS2_Description/meshes/ur10e/collision/chassis/PART20.stl" scale="0.001 0.001 0.001"/>
      </geometry>
    </collision>
    <inertial>
      <origin rpy="0 0 0" xyz="0 0 0"/>
      <mass value="2.75"/>
      <inertia ixx="0.001" ixy="0.0" ixz="0.0" iyy="0.001" iyz="0.0" izz="0.001"/>
    </inertial>
  </link>
  <joint name="sim_ur10e__chassis_to_part20" type="fixed">
    <parent link="sim_ur10e_chassis"/>
    <child link="sim_ur10e_chassis_part20"/>
    <origin rpy="0 0 0" xyz="0 0 0"/>
  </joint>
  <link name="sim_ur10e_chassis_part21">
    <visual>
      <origin rpy="0 0 0" xyz="0 0 0"/>
      <geometry>
        <mesh filename="file:////home/cem/colcon_ws/src/Universal_Robots_ROS2_Description/meshes/ur10e/collision/chassis/PART21.stl" scale="0.001 0.001 0.001"/>
      </geometry>
      <material name="chassis_grey"/>
    </visual>
    <collision>
      <origin rpy="0 0 0" xyz="0 0 0"/>
      <geometry>
        <mesh filename="file:////home/cem/colcon_ws/src/Universal_Robots_ROS2_Description/meshes/ur10e/collision/chassis/PART21.stl" scale="0.001 0.001 0.001"/>
      </geometry>
    </collision>
    <inertial>
      <origin rpy="0 0 0" xyz="0 0 0"/>
      <mass value="2.75"/>
      <inertia ixx="0.001" ixy="0.0" ixz="0.0" iyy="0.001" iyz="0.0" izz="0.001"/>
    </inertial>
  </link>
  <joint name="sim_ur10e__chassis_to_part21" type="fixed">
    <parent link="sim_ur10e_chassis"/>
    <child link="sim_ur10e_chassis_part21"/>
    <origin rpy="0 0 0" xyz="0 0 0"/>
  </joint>
  <link name="sim_ur10e_chassis_part22">
    <visual>
      <origin rpy="0 0 0" xyz="0 0 0"/>
      <geometry>
        <mesh filename="file:////home/cem/colcon_ws/src/Universal_Robots_ROS2_Description/meshes/ur10e/collision/chassis/PART22.stl" scale="0.001 0.001 0.001"/>
      </geometry>
      <material name="chassis_grey"/>
    </visual>
    <collision>
      <origin rpy="0 0 0" xyz="0 0 0"/>
      <geometry>
        <mesh filename="file:////home/cem/colcon_ws/src/Universal_Robots_ROS2_Description/meshes/ur10e/collision/chassis/PART22.stl" scale="0.001 0.001 0.001"/>
      </geometry>
    </collision>
    <inertial>
      <origin rpy="0 0 0" xyz="0 0 0"/>
      <mass value="2.75"/>
      <inertia ixx="0.001" ixy="0.0" ixz="0.0" iyy="0.001" iyz="0.0" izz="0.001"/>
    </inertial>
  </link>
  <joint name="sim_ur10e__chassis_to_part22" type="fixed">
    <parent link="sim_ur10e_chassis"/>
    <child link="sim_ur10e_chassis_part22"/>
    <origin rpy="0 0 0" xyz="0 0 0"/>
  </joint>
  <link name="sim_ur10e_chassis_part23">
    <visual>
      <origin rpy="0 0 0" xyz="0 0 0"/>
      <geometry>
        <mesh filename="file:////home/cem/colcon_ws/src/Universal_Robots_ROS2_Description/meshes/ur10e/collision/chassis/PART23.stl" scale="0.001 0.001 0.001"/>
      </geometry>
      <material name="chassis_grey"/>
    </visual>
    <collision>
      <origin rpy="0 0 0" xyz="0 0 0"/>
      <geometry>
        <mesh filename="file:////home/cem/colcon_ws/src/Universal_Robots_ROS2_Description/meshes/ur10e/collision/chassis/PART23.stl" scale="0.001 0.001 0.001"/>
      </geometry>
    </collision>
    <inertial>
      <origin rpy="0 0 0" xyz="0 0 0"/>
      <mass value="2.75"/>
      <inertia ixx="0.001" ixy="0.0" ixz="0.0" iyy="0.001" iyz="0.0" izz="0.001"/>
    </inertial>
  </link>
  <joint name="sim_ur10e__chassis_to_part23" type="fixed">
    <parent link="sim_ur10e_chassis"/>
    <child link="sim_ur10e_chassis_part23"/>
    <origin rpy="0 0 0" xyz="0 0 0"/>
  </joint>
  <link name="sim_ur10e_chassis_part24">
    <visual>
      <origin rpy="0 0 0" xyz="0 0 0"/>
      <geometry>
        <mesh filename="file:////home/cem/colcon_ws/src/Universal_Robots_ROS2_Description/meshes/ur10e/collision/chassis/PART24.stl" scale="0.001 0.001 0.001"/>
      </geometry>
      <material name="chassis_grey"/>
    </visual>
    <collision>
      <origin rpy="0 0 0" xyz="0 0 0"/>
      <geometry>
        <mesh filename="file:////home/cem/colcon_ws/src/Universal_Robots_ROS2_Description/meshes/ur10e/collision/chassis/PART24.stl" scale="0.001 0.001 0.001"/>
      </geometry>
    </collision>
    <inertial>
      <origin rpy="0 0 0" xyz="0 0 0"/>
      <mass value="2.75"/>
      <inertia ixx="0.001" ixy="0.0" ixz="0.0" iyy="0.001" iyz="0.0" izz="0.001"/>
    </inertial>
  </link>
  <joint name="sim_ur10e__chassis_to_part24" type="fixed">
    <parent link="sim_ur10e_chassis"/>
    <child link="sim_ur10e_chassis_part24"/>
    <origin rpy="0 0 0" xyz="0 0 0"/>
  </joint>
  <link name="sim_ur10e_chassis_part25">
    <visual>
      <origin rpy="0 0 0" xyz="0 0 0"/>
      <geometry>
        <mesh filename="file:////home/cem/colcon_ws/src/Universal_Robots_ROS2_Description/meshes/ur10e/collision/chassis/PART25.stl" scale="0.001 0.001 0.001"/>
      </geometry>
      <material name="chassis_grey"/>
    </visual>
    <collision>
      <origin rpy="0 0 0" xyz="0 0 0"/>
      <geometry>
        <mesh filename="file:////home/cem/colcon_ws/src/Universal_Robots_ROS2_Description/meshes/ur10e/collision/chassis/PART25.stl" scale="0.001 0.001 0.001"/>
      </geometry>
    </collision>
    <inertial>
      <origin rpy="0 0 0" xyz="0 0 0"/>
      <mass value="2.75"/>
      <inertia ixx="0.001" ixy="0.0" ixz="0.0" iyy="0.001" iyz="0.0" izz="0.001"/>
    </inertial>
  </link>
  <joint name="sim_ur10e__chassis_to_part25" type="fixed">
    <parent link="sim_ur10e_chassis"/>
    <child link="sim_ur10e_chassis_part25"/>
    <origin rpy="0 0 0" xyz="0 0 0"/>
  </joint>
  <link name="sim_ur10e_chassis_part26">
    <visual>
      <origin rpy="0 0 0" xyz="0 0 0"/>
      <geometry>
        <mesh filename="file:////home/cem/colcon_ws/src/Universal_Robots_ROS2_Description/meshes/ur10e/collision/chassis/PART26.stl" scale="0.001 0.001 0.001"/>
      </geometry>
      <material name="chassis_grey"/>
    </visual>
    <collision>
      <origin rpy="0 0 0" xyz="0 0 0"/>
      <geometry>
        <mesh filename="file:////home/cem/colcon_ws/src/Universal_Robots_ROS2_Description/meshes/ur10e/collision/chassis/PART26.stl" scale="0.001 0.001 0.001"/>
      </geometry>
    </collision>
    <inertial>
      <origin rpy="0 0 0" xyz="0 0 0"/>
      <mass value="2.75"/>
      <inertia ixx="0.001" ixy="0.0" ixz="0.0" iyy="0.001" iyz="0.0" izz="0.001"/>
    </inertial>
  </link>
  <joint name="sim_ur10e__chassis_to_part26" type="fixed">
    <parent link="sim_ur10e_chassis"/>
    <child link="sim_ur10e_chassis_part26"/>
    <origin rpy="0 0 0" xyz="0 0 0"/>
  </joint>
  <link name="sim_ur10e_chassis_part27">
    <visual>
      <origin rpy="0 0 0" xyz="0 0 0"/>
      <geometry>
        <mesh filename="file:////home/cem/colcon_ws/src/Universal_Robots_ROS2_Description/meshes/ur10e/collision/chassis/PART27.stl" scale="0.001 0.001 0.001"/>
      </geometry>
      <material name="chassis_grey"/>
    </visual>
    <collision>
      <origin rpy="0 0 0" xyz="0 0 0"/>
      <geometry>
        <mesh filename="file:////home/cem/colcon_ws/src/Universal_Robots_ROS2_Description/meshes/ur10e/collision/chassis/PART27.stl" scale="0.001 0.001 0.001"/>
      </geometry>
    </collision>
    <inertial>
      <origin rpy="0 0 0" xyz="0 0 0"/>
      <mass value="2.75"/>
      <inertia ixx="0.001" ixy="0.0" ixz="0.0" iyy="0.001" iyz="0.0" izz="0.001"/>
    </inertial>
  </link>
  <joint name="sim_ur10e__chassis_to_part27" type="fixed">
    <parent link="sim_ur10e_chassis"/>
    <child link="sim_ur10e_chassis_part27"/>
    <origin rpy="0 0 0" xyz="0 0 0"/>
  </joint>
  <link name="sim_ur10e_chassis_part28">
    <visual>
      <origin rpy="0 0 0" xyz="0 0 0"/>
      <geometry>
        <mesh filename="file:////home/cem/colcon_ws/src/Universal_Robots_ROS2_Description/meshes/ur10e/collision/chassis/PART28.stl" scale="0.001 0.001 0.001"/>
      </geometry>
      <material name="chassis_grey"/>
    </visual>
    <collision>
      <origin rpy="0 0 0" xyz="0 0 0"/>
      <geometry>
        <mesh filename="file:////home/cem/colcon_ws/src/Universal_Robots_ROS2_Description/meshes/ur10e/collision/chassis/PART28.stl" scale="0.001 0.001 0.001"/>
      </geometry>
    </collision>
    <inertial>
      <origin rpy="0 0 0" xyz="0 0 0"/>
      <mass value="2.75"/>
      <inertia ixx="0.001" ixy="0.0" ixz="0.0" iyy="0.001" iyz="0.0" izz="0.001"/>
    </inertial>
  </link>
  <joint name="sim_ur10e__chassis_to_part28" type="fixed">
    <parent link="sim_ur10e_chassis"/>
    <child link="sim_ur10e_chassis_part28"/>
    <origin rpy="0 0 0" xyz="0 0 0"/>
  </joint>
  <link name="sim_ur10e_chassis_part29">
    <visual>
      <origin rpy="0 0 0" xyz="0 0 0"/>
      <geometry>
        <mesh filename="file:////home/cem/colcon_ws/src/Universal_Robots_ROS2_Description/meshes/ur10e/collision/chassis/PART29.stl" scale="0.001 0.001 0.001"/>
      </geometry>
      <material name="chassis_grey"/>
    </visual>
    <collision>
      <origin rpy="0 0 0" xyz="0 0 0"/>
      <geometry>
        <mesh filename="file:////home/cem/colcon_ws/src/Universal_Robots_ROS2_Description/meshes/ur10e/collision/chassis/PART29.stl" scale="0.001 0.001 0.001"/>
      </geometry>
    </collision>
    <inertial>
      <origin rpy="0 0 0" xyz="0 0 0"/>
      <mass value="2.75"/>
      <inertia ixx="0.001" ixy="0.0" ixz="0.0" iyy="0.001" iyz="0.0" izz="0.001"/>
    </inertial>
  </link>
  <joint name="sim_ur10e__chassis_to_part29" type="fixed">
    <parent link="sim_ur10e_chassis"/>
    <child link="sim_ur10e_chassis_part29"/>
    <origin rpy="0 0 0" xyz="0 0 0"/>
  </joint>
  <link name="sim_ur10e_chassis_part30">
    <visual>
      <origin rpy="0 0 0" xyz="0 0 0"/>
      <geometry>
        <mesh filename="file:////home/cem/colcon_ws/src/Universal_Robots_ROS2_Description/meshes/ur10e/collision/chassis/PART30.stl" scale="0.001 0.001 0.001"/>
      </geometry>
      <material name="chassis_grey"/>
    </visual>
    <collision>
      <origin rpy="0 0 0" xyz="0 0 0"/>
      <geometry>
        <mesh filename="file:////home/cem/colcon_ws/src/Universal_Robots_ROS2_Description/meshes/ur10e/collision/chassis/PART30.stl" scale="0.001 0.001 0.001"/>
      </geometry>
    </collision>
    <inertial>
      <origin rpy="0 0 0" xyz="0 0 0"/>
      <mass value="2.75"/>
      <inertia ixx="0.001" ixy="0.0" ixz="0.0" iyy="0.001" iyz="0.0" izz="0.001"/>
    </inertial>
  </link>
  <joint name="sim_ur10e__chassis_to_part30" type="fixed">
    <parent link="sim_ur10e_chassis"/>
    <child link="sim_ur10e_chassis_part30"/>
    <origin rpy="0 0 0" xyz="0 0 0"/>
  </joint>
  <link name="sim_ur10e_chassis_part31">
    <visual>
      <origin rpy="0 0 0" xyz="0 0 0"/>
      <geometry>
        <mesh filename="file:////home/cem/colcon_ws/src/Universal_Robots_ROS2_Description/meshes/ur10e/collision/chassis/PART31.stl" scale="0.001 0.001 0.001"/>
      </geometry>
      <material name="chassis_grey"/>
    </visual>
    <collision>
      <origin rpy="0 0 0" xyz="0 0 0"/>
      <geometry>
        <mesh filename="file:////home/cem/colcon_ws/src/Universal_Robots_ROS2_Description/meshes/ur10e/collision/chassis/PART31.stl" scale="0.001 0.001 0.001"/>
      </geometry>
    </collision>
    <inertial>
      <origin rpy="0 0 0" xyz="0 0 0"/>
      <mass value="2.75"/>
      <inertia ixx="0.001" ixy="0.0" ixz="0.0" iyy="0.001" iyz="0.0" izz="0.001"/>
    </inertial>
  </link>
  <joint name="sim_ur10e__chassis_to_part31" type="fixed">
    <parent link="sim_ur10e_chassis"/>
    <child link="sim_ur10e_chassis_part31"/>
    <origin rpy="0 0 0" xyz="0 0 0"/>
  </joint>
  <link name="sim_ur10e_chassis_part32">
    <visual>
      <origin rpy="0 0 0" xyz="0 0 0"/>
      <geometry>
        <mesh filename="file:////home/cem/colcon_ws/src/Universal_Robots_ROS2_Description/meshes/ur10e/collision/chassis/PART32.stl" scale="0.001 0.001 0.001"/>
      </geometry>
      <material name="chassis_grey"/>
    </visual>
    <collision>
      <origin rpy="0 0 0" xyz="0 0 0"/>
      <geometry>
        <mesh filename="file:////home/cem/colcon_ws/src/Universal_Robots_ROS2_Description/meshes/ur10e/collision/chassis/PART32.stl" scale="0.001 0.001 0.001"/>
      </geometry>
    </collision>
    <inertial>
      <origin rpy="0 0 0" xyz="0 0 0"/>
      <mass value="2.75"/>
      <inertia ixx="0.001" ixy="0.0" ixz="0.0" iyy="0.001" iyz="0.0" izz="0.001"/>
    </inertial>
  </link>
  <joint name="sim_ur10e__chassis_to_part32" type="fixed">
    <parent link="sim_ur10e_chassis"/>
    <child link="sim_ur10e_chassis_part32"/>
    <origin rpy="0 0 0" xyz="0 0 0"/>
  </joint>
  <link name="sim_ur10e_chassis_part33">
    <visual>
      <origin rpy="0 0 0" xyz="0 0 0"/>
      <geometry>
        <mesh filename="file:////home/cem/colcon_ws/src/Universal_Robots_ROS2_Description/meshes/ur10e/collision/chassis/PART33.stl" scale="0.001 0.001 0.001"/>
      </geometry>
      <material name="chassis_grey"/>
    </visual>
    <collision>
      <origin rpy="0 0 0" xyz="0 0 0"/>
      <geometry>
        <mesh filename="file:////home/cem/colcon_ws/src/Universal_Robots_ROS2_Description/meshes/ur10e/collision/chassis/PART33.stl" scale="0.001 0.001 0.001"/>
      </geometry>
    </collision>
    <inertial>
      <origin rpy="0 0 0" xyz="0 0 0"/>
      <mass value="2.75"/>
      <inertia ixx="0.001" ixy="0.0" ixz="0.0" iyy="0.001" iyz="0.0" izz="0.001"/>
    </inertial>
  </link>
  <joint name="sim_ur10e__chassis_to_part33" type="fixed">
    <parent link="sim_ur10e_chassis"/>
    <child link="sim_ur10e_chassis_part33"/>
    <origin rpy="0 0 0" xyz="0 0 0"/>
  </joint>
  <link name="sim_ur10e_chassis_part34">
    <visual>
      <origin rpy="0 0 0" xyz="0 0 0"/>
      <geometry>
        <mesh filename="file:////home/cem/colcon_ws/src/Universal_Robots_ROS2_Description/meshes/ur10e/collision/chassis/PART34.stl" scale="0.001 0.001 0.001"/>
      </geometry>
      <material name="chassis_grey"/>
    </visual>
    <collision>
      <origin rpy="0 0 0" xyz="0 0 0"/>
      <geometry>
        <mesh filename="file:////home/cem/colcon_ws/src/Universal_Robots_ROS2_Description/meshes/ur10e/collision/chassis/PART34.stl" scale="0.001 0.001 0.001"/>
      </geometry>
    </collision>
    <inertial>
      <origin rpy="0 0 0" xyz="0 0 0"/>
      <mass value="2.75"/>
      <inertia ixx="0.001" ixy="0.0" ixz="0.0" iyy="0.001" iyz="0.0" izz="0.001"/>
    </inertial>
  </link>
  <joint name="sim_ur10e__chassis_to_part34" type="fixed">
    <parent link="sim_ur10e_chassis"/>
    <child link="sim_ur10e_chassis_part34"/>
    <origin rpy="0 0 0" xyz="0 0 0"/>
  </joint>
  <link name="sim_ur10e_chassis_part35">
    <visual>
      <origin rpy="0 0 0" xyz="0 0 0"/>
      <geometry>
        <mesh filename="file:////home/cem/colcon_ws/src/Universal_Robots_ROS2_Description/meshes/ur10e/collision/chassis/PART35.stl" scale="0.001 0.001 0.001"/>
      </geometry>
      <material name="chassis_grey"/>
    </visual>
    <collision>
      <origin rpy="0 0 0" xyz="0 0 0"/>
      <geometry>
        <mesh filename="file:////home/cem/colcon_ws/src/Universal_Robots_ROS2_Description/meshes/ur10e/collision/chassis/PART35.stl" scale="0.001 0.001 0.001"/>
      </geometry>
    </collision>
    <inertial>
      <origin rpy="0 0 0" xyz="0 0 0"/>
      <mass value="2.75"/>
      <inertia ixx="0.001" ixy="0.0" ixz="0.0" iyy="0.001" iyz="0.0" izz="0.001"/>
    </inertial>
  </link>
  <joint name="sim_ur10e__chassis_to_part35" type="fixed">
    <parent link="sim_ur10e_chassis"/>
    <child link="sim_ur10e_chassis_part35"/>
    <origin rpy="0 0 0" xyz="0 0 0"/>
  </joint>
  <link name="sim_ur10e_chassis_part36">
    <visual>
      <origin rpy="0 0 0" xyz="0 0 0"/>
      <geometry>
        <mesh filename="file:////home/cem/colcon_ws/src/Universal_Robots_ROS2_Description/meshes/ur10e/collision/chassis/PART36.stl" scale="0.001 0.001 0.001"/>
      </geometry>
      <material name="chassis_grey"/>
    </visual>
    <collision>
      <origin rpy="0 0 0" xyz="0 0 0"/>
      <geometry>
        <mesh filename="file:////home/cem/colcon_ws/src/Universal_Robots_ROS2_Description/meshes/ur10e/collision/chassis/PART36.stl" scale="0.001 0.001 0.001"/>
      </geometry>
    </collision>
    <inertial>
      <origin rpy="0 0 0" xyz="0 0 0"/>
      <mass value="2.75"/>
      <inertia ixx="0.001" ixy="0.0" ixz="0.0" iyy="0.001" iyz="0.0" izz="0.001"/>
    </inertial>
  </link>
  <joint name="sim_ur10e__chassis_to_part36" type="fixed">
    <parent link="sim_ur10e_chassis"/>
    <child link="sim_ur10e_chassis_part36"/>
    <origin rpy="0 0 0" xyz="0 0 0"/>
  </joint>
  <link name="sim_ur10e_chassis_part37">
    <visual>
      <origin rpy="0 0 0" xyz="0 0 0"/>
      <geometry>
        <mesh filename="file:////home/cem/colcon_ws/src/Universal_Robots_ROS2_Description/meshes/ur10e/collision/chassis/PART37.stl" scale="0.001 0.001 0.001"/>
      </geometry>
      <material name="chassis_grey"/>
    </visual>
    <collision>
      <origin rpy="0 0 0" xyz="0 0 0"/>
      <geometry>
        <mesh filename="file:////home/cem/colcon_ws/src/Universal_Robots_ROS2_Description/meshes/ur10e/collision/chassis/PART37.stl" scale="0.001 0.001 0.001"/>
      </geometry>
    </collision>
    <inertial>
      <origin rpy="0 0 0" xyz="0 0 0"/>
      <mass value="2.75"/>
      <inertia ixx="0.001" ixy="0.0" ixz="0.0" iyy="0.001" iyz="0.0" izz="0.001"/>
    </inertial>
  </link>
  <joint name="sim_ur10e__chassis_to_part37" type="fixed">
    <parent link="sim_ur10e_chassis"/>
    <child link="sim_ur10e_chassis_part37"/>
    <origin rpy="0 0 0" xyz="0 0 0"/>
  </joint>
  <link name="sim_ur10e_chassis_part38">
    <visual>
      <origin rpy="0 0 0" xyz="0 0 0"/>
      <geometry>
        <mesh filename="file:////home/cem/colcon_ws/src/Universal_Robots_ROS2_Description/meshes/ur10e/collision/chassis/PART38.stl" scale="0.001 0.001 0.001"/>
      </geometry>
      <material name="chassis_grey"/>
    </visual>
    <collision>
      <origin rpy="0 0 0" xyz="0 0 0"/>
      <geometry>
        <mesh filename="file:////home/cem/colcon_ws/src/Universal_Robots_ROS2_Description/meshes/ur10e/collision/chassis/PART38.stl" scale="0.001 0.001 0.001"/>
      </geometry>
    </collision>
    <inertial>
      <origin rpy="0 0 0" xyz="0 0 0"/>
      <mass value="2.75"/>
      <inertia ixx="0.001" ixy="0.0" ixz="0.0" iyy="0.001" iyz="0.0" izz="0.001"/>
    </inertial>
  </link>
  <joint name="sim_ur10e__chassis_to_part38" type="fixed">
    <parent link="sim_ur10e_chassis"/>
    <child link="sim_ur10e_chassis_part38"/>
    <origin rpy="0 0 0" xyz="0 0 0"/>
  </joint>
  <link name="sim_ur10e_chassis_part39">
    <visual>
      <origin rpy="0 0 0" xyz="0 0 0"/>
      <geometry>
        <mesh filename="file:////home/cem/colcon_ws/src/Universal_Robots_ROS2_Description/meshes/ur10e/collision/chassis/PART39.stl" scale="0.001 0.001 0.001"/>
      </geometry>
      <material name="chassis_grey"/>
    </visual>
    <collision>
      <origin rpy="0 0 0" xyz="0 0 0"/>
      <geometry>
        <mesh filename="file:////home/cem/colcon_ws/src/Universal_Robots_ROS2_Description/meshes/ur10e/collision/chassis/PART39.stl" scale="0.001 0.001 0.001"/>
      </geometry>
    </collision>
    <inertial>
      <origin rpy="0 0 0" xyz="0 0 0"/>
      <mass value="2.75"/>
      <inertia ixx="0.001" ixy="0.0" ixz="0.0" iyy="0.001" iyz="0.0" izz="0.001"/>
    </inertial>
  </link>
  <joint name="sim_ur10e__chassis_to_part39" type="fixed">
    <parent link="sim_ur10e_chassis"/>
    <child link="sim_ur10e_chassis_part39"/>
    <origin rpy="0 0 0" xyz="0 0 0"/>
  </joint>
  <link name="sim_ur10e_chassis_part40">
    <visual>
      <origin rpy="0 0 0" xyz="0 0 0"/>
      <geometry>
        <mesh filename="file:////home/cem/colcon_ws/src/Universal_Robots_ROS2_Description/meshes/ur10e/collision/chassis/PART40.stl" scale="0.001 0.001 0.001"/>
      </geometry>
      <material name="chassis_grey"/>
    </visual>
    <collision>
      <origin rpy="0 0 0" xyz="0 0 0"/>
      <geometry>
        <mesh filename="file:////home/cem/colcon_ws/src/Universal_Robots_ROS2_Description/meshes/ur10e/collision/chassis/PART40.stl" scale="0.001 0.001 0.001"/>
      </geometry>
    </collision>
    <inertial>
      <origin rpy="0 0 0" xyz="0 0 0"/>
      <mass value="2.75"/>
      <inertia ixx="0.001" ixy="0.0" ixz="0.0" iyy="0.001" iyz="0.0" izz="0.001"/>
    </inertial>
  </link>
  <joint name="sim_ur10e__chassis_to_part40" type="fixed">
    <parent link="sim_ur10e_chassis"/>
    <child link="sim_ur10e_chassis_part40"/>
    <origin rpy="0 0 0" xyz="0 0 0"/>
  </joint>
  <link name="sim_ur10e_chassis_part41">
    <visual>
      <origin rpy="0 0 0" xyz="0 0 0"/>
      <geometry>
        <mesh filename="file:////home/cem/colcon_ws/src/Universal_Robots_ROS2_Description/meshes/ur10e/collision/chassis/PART41.stl" scale="0.001 0.001 0.001"/>
      </geometry>
      <material name="chassis_grey"/>
    </visual>
    <collision>
      <origin rpy="0 0 0" xyz="0 0 0"/>
      <geometry>
        <mesh filename="file:////home/cem/colcon_ws/src/Universal_Robots_ROS2_Description/meshes/ur10e/collision/chassis/PART41.stl" scale="0.001 0.001 0.001"/>
      </geometry>
    </collision>
    <inertial>
      <origin rpy="0 0 0" xyz="0 0 0"/>
      <mass value="2.75"/>
      <inertia ixx="0.001" ixy="0.0" ixz="0.0" iyy="0.001" iyz="0.0" izz="0.001"/>
    </inertial>
  </link>
  <joint name="sim_ur10e__chassis_to_part41" type="fixed">
    <parent link="sim_ur10e_chassis"/>
    <child link="sim_ur10e_chassis_part41"/>
    <origin rpy="0 0 0" xyz="0 0 0"/>
  </joint>
  <link name="sim_ur10e_chassis_part42">
    <visual>
      <origin rpy="0 0 0" xyz="0 0 0"/>
      <geometry>
        <mesh filename="file:////home/cem/colcon_ws/src/Universal_Robots_ROS2_Description/meshes/ur10e/collision/chassis/PART42.stl" scale="0.001 0.001 0.001"/>
      </geometry>
      <material name="chassis_grey"/>
    </visual>
    <collision>
      <origin rpy="0 0 0" xyz="0 0 0"/>
      <geometry>
        <mesh filename="file:////home/cem/colcon_ws/src/Universal_Robots_ROS2_Description/meshes/ur10e/collision/chassis/PART42.stl" scale="0.001 0.001 0.001"/>
      </geometry>
    </collision>
    <inertial>
      <origin rpy="0 0 0" xyz="0 0 0"/>
      <mass value="2.75"/>
      <inertia ixx="0.001" ixy="0.0" ixz="0.0" iyy="0.001" iyz="0.0" izz="0.001"/>
    </inertial>
  </link>
  <joint name="sim_ur10e__chassis_to_part42" type="fixed">
    <parent link="sim_ur10e_chassis"/>
    <child link="sim_ur10e_chassis_part42"/>
    <origin rpy="0 0 0" xyz="0 0 0"/>
  </joint>
  <link name="sim_ur10e_chassis_part43">
    <visual>
      <origin rpy="0 0 0" xyz="0 0 0"/>
      <geometry>
        <mesh filename="file:////home/cem/colcon_ws/src/Universal_Robots_ROS2_Description/meshes/ur10e/collision/chassis/PART43.stl" scale="0.001 0.001 0.001"/>
      </geometry>
      <material name="chassis_grey"/>
    </visual>
    <collision>
      <origin rpy="0 0 0" xyz="0 0 0"/>
      <geometry>
        <mesh filename="file:////home/cem/colcon_ws/src/Universal_Robots_ROS2_Description/meshes/ur10e/collision/chassis/PART43.stl" scale="0.001 0.001 0.001"/>
      </geometry>
    </collision>
    <inertial>
      <origin rpy="0 0 0" xyz="0 0 0"/>
      <mass value="2.75"/>
      <inertia ixx="0.001" ixy="0.0" ixz="0.0" iyy="0.001" iyz="0.0" izz="0.001"/>
    </inertial>
  </link>
  <joint name="sim_ur10e__chassis_to_part43" type="fixed">
    <parent link="sim_ur10e_chassis"/>
    <child link="sim_ur10e_chassis_part43"/>
    <origin rpy="0 0 0" xyz="0 0 0"/>
  </joint>
  <link name="sim_ur10e_chassis_part44">
    <visual>
      <origin rpy="0 0 0" xyz="0 0 0"/>
      <geometry>
        <mesh filename="file:////home/cem/colcon_ws/src/Universal_Robots_ROS2_Description/meshes/ur10e/collision/chassis/PART44.stl" scale="0.001 0.001 0.001"/>
      </geometry>
      <material name="chassis_grey"/>
    </visual>
    <collision>
      <origin rpy="0 0 0" xyz="0 0 0"/>
      <geometry>
        <mesh filename="file:////home/cem/colcon_ws/src/Universal_Robots_ROS2_Description/meshes/ur10e/collision/chassis/PART44.stl" scale="0.001 0.001 0.001"/>
      </geometry>
    </collision>
    <inertial>
      <origin rpy="0 0 0" xyz="0 0 0"/>
      <mass value="2.75"/>
      <inertia ixx="0.001" ixy="0.0" ixz="0.0" iyy="0.001" iyz="0.0" izz="0.001"/>
    </inertial>
  </link>
  <joint name="sim_ur10e__chassis_to_part44" type="fixed">
    <parent link="sim_ur10e_chassis"/>
    <child link="sim_ur10e_chassis_part44"/>
    <origin rpy="0 0 0" xyz="0 0 0"/>
  </joint>
  <!-- Gazebo için renk tanımlamaları -->
  <gazebo reference="sim_ur10e_chassis_part17">
    <material>Gazebo/Red</material>
  </gazebo>
  <!-- <gazebo reference="${tf_prefix}chassis_part23">
      <material>Gazebo/Red</material>
    </gazebo> -->
  <link name="sim_ur10e_robot_mount">
    <inertial>
      <origin rpy="0 0 0" xyz="0.04578298705746098 0.1200817119996848 0.03993803302086685"/>
      <mass value="14.04925448455695"/>
      <inertia ixx="0.061984" ixy="-0.003503" ixz="0.001551" iyy="0.069314" iyz="0.000564" izz="0.125682"/>
    </inertial>
    <visual>
      <origin rpy="0 0 0" xyz="0.147 -0.115 -0.58635"/>
      <geometry>
        <mesh filename="file:////home/cem/colcon_ws/src/Universal_Robots_ROS2_Description/meshes/ur10e/collision/linear_axis_moving_link.stl" scale="0.001 0.001 0.001"/>
      </geometry>
      <material name="silver"/>
    </visual>
    <collision>
      <origin rpy="0 0 0" xyz="0.147 -0.115 -0.58635"/>
      <geometry>
        <mesh filename="file:////home/cem/colcon_ws/src/Universal_Robots_ROS2_Description/meshes/ur10e/collision/linear_axis_moving_link.stl" scale="0.001 0.001 0.001"/>
      </geometry>
    </collision>
  </link>
  <!-- <link name="${tf_prefix}wall_door">
      <inertial>
        <origin rpy="0 0 0" xyz="600.0 3235.0 550.0"/>
        <mass value="8.04925448455695"/>
        <inertia ixx="10.53" ixy="0.0" ixz="0.0" iyy="22.88" iyz="0.0" izz="12.52"/>
      </inertial>
      <visual>
        <origin rpy="0 0 0" xyz="0 0 0"/>
        <geometry>
          <mesh filename="file:////home/cem/colcon_ws/src/Universal_Robots_ROS2_Description/meshes/ur10e/collision/wall_door.stl" scale="0.001 0.001 0.001"/>
        </geometry>
        <material name="silver"/>
      </visual>
      <collision>
        <origin rpy="0 0 0" xyz="0 0 0"/>
        <geometry>
          <mesh filename="file:////home/cem/colcon_ws/src/Universal_Robots_ROS2_Description/meshes/ur10e/collision/wall_door.stl" scale="0.001 0.001 0.001"/>
        </geometry>
      </collision>
    </link>

    <link name="${tf_prefix}wall_server">
      <inertial>
        <origin rpy="0 0 0" xyz="-175.0 -1020.0 550.0"/>
        <mass value="12.04925448455695"/>
        <inertia ixx="24.14" ixy="0.0" ixz="0.0" iyy="17.36" iyz="0.0" izz="14.98"/>
      </inertial>
      <visual>
        <origin rpy="0 0 0" xyz="0 0 0"/>
        <geometry>
          <mesh filename="file:////home/cem/colcon_ws/src/Universal_Robots_ROS2_Description/meshes/ur10e/collision/wall_server.stl" scale="0.001 0.001 0.001"/>
        </geometry>
        <material name="silver"/>
      </visual>
      <collision>
        <origin rpy="0 0 0" xyz="0 0 0"/>
        <geometry>
          <mesh filename="file:////home/cem/colcon_ws/src/Universal_Robots_ROS2_Description/meshes/ur10e/collision/wall_server.stl" scale="0.001 0.001 0.001"/>
        </geometry>
      </collision>
    </link> -->
  <link name="sim_ur10e_alumunium_table">
    <inertial>
      <origin rpy="0 0 0" xyz="681.141 2464.643 737.851"/>
      <mass value="20.04925448455695"/>
      <inertia ixx="130.9" ixy="0.04503" ixz="0.9303" iyy="70.758" iyz="-0.03313" izz="139.1"/>
    </inertial>
    <visual>
      <origin rpy="0 0 0" xyz="0 0 0"/>
      <geometry>
        <mesh filename="file:////home/cem/colcon_ws/src/Universal_Robots_ROS2_Description/meshes/ur10e/collision/alumuniumtable.stl" scale="0.001 0.001 0.001"/>
      </geometry>
      <material name="silver"/>
    </visual>
    <collision>
      <origin rpy="0 0 0" xyz="0 0 0"/>
      <geometry>
        <mesh filename="file:////home/cem/colcon_ws/src/Universal_Robots_ROS2_Description/meshes/ur10e/collision/alumuniumtable.stl" scale="0.001 0.001 0.001"/>
      </geometry>
    </collision>
  </link>
  <link name="sim_ur10e_conveyor_belt">
    <inertial>
      <origin rpy="0 0 0" xyz="736.828 104.977 664.295"/>
      <mass value="15.04925448455695"/>
      <inertia ixx="0.061984" ixy="-0.003503" ixz="0.001551" iyy="0.069314" iyz="0.000564" izz="0.125682"/>
    </inertial>
    <visual>
      <origin rpy="0 0 0" xyz="0 0 0"/>
      <geometry>
        <mesh filename="file:////home/cem/colcon_ws/src/Universal_Robots_ROS2_Description/meshes/ur10e/collision/conveyorbelt.stl" scale="0.001 0.001 0.001"/>
      </geometry>
      <material name="silver"/>
    </visual>
    <collision>
      <origin rpy="0 0 0" xyz="0 0 0"/>
      <geometry>
        <mesh filename="file:////home/cem/colcon_ws/src/Universal_Robots_ROS2_Description/meshes/ur10e/collision/conveyorbelt.stl" scale="0.001 0.001 0.001"/>
      </geometry>
    </collision>
  </link>
  <!-- Joint tanımları -->
  <joint name="sim_ur10e_table_base_joint" type="fixed">
    <origin rpy="0 0 0" xyz="0 0 0"/>
    <parent link="world"/>
    <child link="sim_ur10e_table"/>
  </joint>
  <!-- <joint name="${tf_prefix}base_to_chassis" type="fixed">
      <parent link="${parent}"/>
      <child link="${tf_prefix}chassis"/>
      <origin xyz="0 0 0" rpy="0 0 0"/>
    </joint> -->
  <!-- Linear axis joint - bu joint'in tam tanımı burada olmalı -->
  <joint name="sim_ur10e_base_to_robot_mount" type="prismatic">
    <parent link="sim_ur10e_table"/>
    <child link="sim_ur10e_robot_mount"/>
    <origin rpy="0 0 0" xyz="-0.158 0.115 0.58635"/>
    <axis xyz="0.0 1.0 0.0"/>
    <limit effort="1000" lower="0.05" upper="1.95" velocity="1.25"/>
    <dynamics damping="100.0" friction="50.0"/>
  </joint>
  <joint name="sim_ur10e_base_to_alumuniumtable" type="fixed">
    <parent link="world"/>
    <child link="sim_ur10e_alumunium_table"/>
    <origin rpy="0 0 0" xyz="0 0 0"/>
  </joint>
  <joint name="sim_ur10e_base_to_conveyorbelt" type="fixed">
    <parent link="world"/>
    <child link="sim_ur10e_conveyor_belt"/>
    <origin rpy="0 0 0" xyz="0 0 0"/>
  </joint>
  <!-- <joint name="${tf_prefix}base_to_walldoor" type="fixed">
      <parent link="${parent}"/>
      <child link="${tf_prefix}wall_door"/>
      <origin xyz="0 0 0" rpy="0 0 0"/>
    </joint>

    <joint name="${tf_prefix}base_to_wall_server" type="fixed">
      <parent link="${parent}"/>
      <child link="${tf_prefix}wall_server"/>
      <origin xyz="0 0 0" rpy="0 0 0"/>
    </joint> -->
  <ros2_control name="LinearAxisHardwareInterface" type="system">
    <hardware>
      <plugin>gz_ros2_control/GazeboSimSystem</plugin>
    </hardware>
    <joint name="sim_ur10e_base_to_robot_mount">
      <command_interface name="position">
        <param name="min">0.05</param>
        <param name="max">1.95</param>
      </command_interface>
      <command_interface name="velocity">
        <param name="min">-1.25</param>
        <param name="max">1.25</param>
      </command_interface>
      <state_interface name="position">
        <param name="initial_value">1.0</param>
      </state_interface>
      <state_interface name="velocity"/>
      <state_interface name="effort"/>
    </joint>
  </ros2_control>
  <transmission name="sim_ur10e_linear_axis_transmission">
    <type>transmission_interface/SimpleTransmission</type>
    <joint name="sim_ur10e_base_to_robot_mount">
      <hardwareInterface>hardware_interface/PositionJointInterface</hardwareInterface>
      <hardwareInterface>hardware_interface/VelocityJointInterface</hardwareInterface>
    </joint>
    <actuator name="sim_ur10e_linear_axis_motor">
      <hardwareInterface>hardware_interface/PositionJointInterface</hardwareInterface>
      <hardwareInterface>hardware_interface/VelocityJointInterface</hardwareInterface>
      <mechanicalReduction>1</mechanicalReduction>
    </actuator>
  </transmission>
  <ros2_control name="sim_ur10e_ur10e" type="system">
    <hardware>
      <plugin>gz_ros2_control/GazeboSimSystem</plugin>
    </hardware>
    <joint name="sim_ur10e_shoulder_pan_joint">
      <command_interface name="position"/>
      <command_interface name="velocity"/>
      <state_interface name="position">
        <!-- initial position for the FakeSystem and simulation -->
        <param name="initial_value">0.0</param>
      </state_interface>
      <state_interface name="velocity"/>
      <state_interface name="effort"/>
    </joint>
    <joint name="sim_ur10e_shoulder_lift_joint">
      <command_interface name="position"/>
      <command_interface name="velocity"/>
      <state_interface name="position">
        <!-- initial position for the FakeSystem and simulation -->
        <param name="initial_value">-1.57</param>
      </state_interface>
      <state_interface name="velocity"/>
      <state_interface name="effort"/>
    </joint>
    <joint name="sim_ur10e_elbow_joint">
      <command_interface name="position"/>
      <command_interface name="velocity"/>
      <state_interface name="position">
        <!-- initial position for the FakeSystem and simulation -->
        <param name="initial_value">0.0</param>
      </state_interface>
      <state_interface name="velocity"/>
      <state_interface name="effort"/>
    </joint>
    <joint name="sim_ur10e_wrist_1_joint">
      <command_interface name="position"/>
      <command_interface name="velocity"/>
      <state_interface name="position">
        <!-- initial position for the FakeSystem and simulation -->
        <param name="initial_value">-1.57</param>
      </state_interface>
      <state_interface name="velocity"/>
      <state_interface name="effort"/>
    </joint>
    <joint name="sim_ur10e_wrist_2_joint">
      <command_interface name="position"/>
      <command_interface name="velocity"/>
      <state_interface name="position">
        <!-- initial position for the FakeSystem and simulation -->
        <param name="initial_value">0.0</param>
      </state_interface>
      <state_interface name="velocity"/>
      <state_interface name="effort"/>
    </joint>
    <joint name="sim_ur10e_wrist_3_joint">
      <command_interface name="position"/>
      <command_interface name="velocity"/>
      <state_interface name="position">
        <!-- initial position for the FakeSystem and simulation -->
        <param name="initial_value">0.0</param>
      </state_interface>
      <state_interface name="velocity"/>
      <state_interface name="effort"/>
    </joint>
    <joint name="sim_ur10e_gripper_joint">
      <command_interface name="position"/>
      <state_interface name="position">
        <param name="initial_value">0.0005</param>
      </state_interface>
      <state_interface name="velocity"/>
      <state_interface name="effort"/>
    </joint>
    <joint name="sim_ur10e_gripper_lower_finger_joint">
      <param name="mimic">sim_ur10e_gripper_joint</param>
      <param name="multiplier">-1</param>
      <!-- multiplier=-1: follower moves in opposite direction to match mimic axis convention -->
      <command_interface name="position"/>
      <state_interface name="position"/>
      <state_interface name="velocity"/>
      <state_interface name="effort"/>
    </joint>
  </ros2_control>
  <!-- Add URDF transmission elements (for ros_control) -->
  <!--<xacro:ur_arm_transmission prefix="${prefix}" hw_interface="${transmission_hw_interface}" />-->
  <!-- Placeholder for ros2_control transmission which don't yet exist -->
  <link name="sim_ur10e_base_link"/>
  <link name="sim_ur10e_base_link_inertia">
    <visual>
      <origin rpy="0 0 0" xyz="0.105561 -0.1918 -0.6445"/>
      <geometry>
        <mesh filename="file:////home/cem/colcon_ws/src/Universal_Robots_ROS2_Description/meshes/ur10e/secondrobotvisual/base.stl" scale="0.001 0.001 0.001"/>
      </geometry>
      <material name="silver"/>
    </visual>
    <collision>
      <origin rpy="0 0 0" xyz="0.105561 -0.1918 -0.6445"/>
      <geometry>
        <mesh filename="file:////home/cem/colcon_ws/src/Universal_Robots_ROS2_Description/meshes/ur10e/secondrobotcollision/base.stl" scale="0.001 0.001 0.001"/>
      </geometry>
      <material name="silver"/>
    </collision>
    <inertial>
      <mass value="4.0"/>
      <origin rpy="0 0 0" xyz="0 0 0"/>
      <inertia ixx="0.0061063308908" ixy="0.0" ixz="0.0" iyy="0.0061063308908" iyz="0.0" izz="0.01125"/>
    </inertial>
  </link>
  <link name="sim_ur10e_shoulder_link">
    <visual>
      <origin rpy="0 0 0" xyz="0.105565 -0.1918 -0.74405"/>
      <geometry>
        <mesh filename="file:////home/cem/colcon_ws/src/Universal_Robots_ROS2_Description/meshes/ur10e/secondrobotvisual/shoulder.stl" scale="0.001 0.001 0.001"/>
      </geometry>
      <material name="silver"/>
    </visual>
    <collision>
      <origin rpy="0 0 0" xyz="0.105565 -0.1918 -0.74405"/>
      <geometry>
        <mesh filename="file:////home/cem/colcon_ws/src/Universal_Robots_ROS2_Description/meshes/ur10e/secondrobotcollision/shoulder.stl" scale="0.001 0.001 0.001"/>
      </geometry>
    </collision>
    <inertial>
      <mass value="7.369"/>
      <origin rpy="1.570796326794897 0 0" xyz="0.021 -0.027 0.0"/>
      <inertia ixx="0.03408" ixy="2e-05" ixz="-0.00425" iyy="0.03529" iyz="8e-05" izz="0.02156"/>
    </inertial>
  </link>
  <link name="sim_ur10e_upper_arm_link">
    <visual>
      <origin rpy="0 0 0" xyz="0.105565 -0.2778 -0.83405"/>
      <geometry>
        <mesh filename="file:////home/cem/colcon_ws/src/Universal_Robots_ROS2_Description/meshes/ur10e/secondrobotvisual/upperarm.stl" scale="0.001 0.001 0.001"/>
      </geometry>
      <material name="silver"/>
    </visual>
    <collision>
      <origin rpy="0 0 0" xyz="0.105565 -0.2778 -0.83405"/>
      <geometry>
        <mesh filename="file:////home/cem/colcon_ws/src/Universal_Robots_ROS2_Description/meshes/ur10e/secondrobotcollision/upperarm.stl" scale="0.001 0.001 0.001"/>
      </geometry>
    </collision>
    <inertial>
      <mass value="13.051"/>
      <origin rpy="0 0 0" xyz="-0.2327 0.0 0.158"/>
      <inertia ixx="0.02814" ixy="5e-05" ixz="-0.01561" iyy="0.77068" iyz="2e-05" izz="0.76943"/>
    </inertial>
  </link>
  <link name="sim_ur10e_forearm_link">
    <visual>
      <origin rpy="0 0 0" xyz="-0.506534 -0.299691 -0.833449"/>
      <geometry>
        <mesh filename="file:////home/cem/colcon_ws/src/Universal_Robots_ROS2_Description/meshes/ur10e/secondrobotvisual/forearm.stl" scale="0.001 0.001 0.001"/>
      </geometry>
      <material name="silver"/>
    </visual>
    <collision>
      <origin rpy="0 0 0" xyz="-0.506534 -0.299691 -0.833449"/>
      <geometry>
        <mesh filename="file:////home/cem/colcon_ws/src/Universal_Robots_ROS2_Description/meshes/ur10e/secondrobotcollision/forearm.stl" scale="0.001 0.001 0.001"/>
      </geometry>
    </collision>
    <inertial>
      <mass value="3.989"/>
      <origin rpy="0 0 0" xyz="-0.33155 0.0 0.068"/>
      <inertia ixx="0.01014" ixy="8e-05" ixz="0.00916" iyy="0.30928" iyz="0.0" izz="0.30646"/>
    </inertial>
  </link>
  <link name="sim_ur10e_wrist_1_link">
    <visual>
      <origin rpy="0 0 0" xyz="-1.078132 -0.301691 -0.833449"/>
      <geometry>
        <mesh filename="file:////home/cem/colcon_ws/src/Universal_Robots_ROS2_Description/meshes/ur10e/secondrobotvisual/wrist1.stl" scale="0.001 0.001 0.001"/>
      </geometry>
      <material name="silver"/>
    </visual>
    <collision>
      <origin rpy="0 0 0" xyz="-1.078132 -0.301691 -0.833449"/>
      <geometry>
        <mesh filename="file:////home/cem/colcon_ws/src/Universal_Robots_ROS2_Description/meshes/ur10e/secondrobotcollision/wrist1.stl" scale="0.001 0.001 0.001"/>
      </geometry>
    </collision>
    <inertial>
      <mass value="2.1"/>
      <origin rpy="1.570796326794897 0 0" xyz="0.0 -0.018 0.007"/>
      <inertia ixx="0.00296" ixy="-1e-05" ixz="0.0" iyy="0.00222" iyz="-0.00024" izz="0.00258"/>
    </inertial>
  </link>
  <link name="sim_ur10e_wrist_2_link">
    <visual>
      <origin rpy="0 0 0" xyz="-1.078132 -0.355691 -0.77175"/>
      <geometry>
        <mesh filename="file:////home/cem/colcon_ws/src/Universal_Robots_ROS2_Description/meshes/ur10e/secondrobotvisual/wrist2.stl" scale="0.001 0.001 0.001"/>
      </geometry>
      <material name="silver"/>
    </visual>
    <collision>
      <origin rpy="0 0 0" xyz="-1.078132 -0.355691 -0.77175"/>
      <geometry>
        <mesh filename="file:////home/cem/colcon_ws/src/Universal_Robots_ROS2_Description/meshes/ur10e/secondrobotcollision/wrist2.stl" scale="0.001 0.001 0.001"/>
      </geometry>
    </collision>
    <inertial>
      <mass value="1.98"/>
      <origin rpy="-1.570796326794897 0 0" xyz="0.0 0.018 -0.007"/>
      <inertia ixx="0.00296" ixy="-1e-05" ixz="0.0" iyy="0.00222" iyz="-0.00024" izz="0.00258"/>
    </inertial>
  </link>
  <link name="sim_ur10e_wrist_3_link">
    <visual>
      <origin rpy="0 0 0" xyz="-1.078132 -0.417389 -0.71775"/>
      <geometry>
        <mesh filename="file:////home/cem/colcon_ws/src/Universal_Robots_ROS2_Description/meshes/ur10e/secondrobotvisual/wrist3.stl" scale="0.001 0.001 0.001"/>
      </geometry>
      <material name="silver"/>
    </visual>
    <collision>
      <origin rpy="0 0 0" xyz="-1.078132 -0.417389 -0.71775"/>
      <geometry>
        <mesh filename="file:////home/cem/colcon_ws/src/Universal_Robots_ROS2_Description/meshes/ur10e/secondrobotcollision/wrist3.stl" scale="0.001 0.001 0.001"/>
      </geometry>
    </collision>
    <inertial>
      <mass value="0.615"/>
      <origin rpy="0 0 0" xyz="0.0 0.0 -0.026"/>
      <inertia ixx="0.0004" ixy="0.0" ixz="0.0" iyy="0.00041" iyz="0.0" izz="0.00034"/>
    </inertial>
  </link>
  <!-- base_joint fixes base_link to the environment -->
  <joint name="sim_ur10e_base_joint" type="fixed">
    <origin rpy="0 0 0" xyz="0 0 0"/>
    <parent link="sim_ur10e_robot_mount"/>
    <child link="sim_ur10e_base_link"/>
  </joint>
  <!-- joints - main serial chain -->
  <joint name="sim_ur10e_base_link-base_link_inertia" type="fixed">
    <parent link="sim_ur10e_base_link"/>
    <child link="sim_ur10e_base_link_inertia"/>
    <!-- 'base_link' is REP-103 aligned (so X+ forward), while the internal
           frames of the robot/controller have X+ pointing backwards.
           Use the joint between 'base_link' and 'base_link_inertia' (a dummy
           link/frame) to introduce the necessary rotation over Z (of pi rad).
      -->
    <origin rpy="0 0 0" xyz="0.052439 0.0768 0.05815"/>
  </joint>
  <joint name="sim_ur10e_shoulder_pan_joint" type="revolute">
    <parent link="sim_ur10e_base_link_inertia"/>
    <child link="sim_ur10e_shoulder_link"/>
    <origin rpy="0 0 0" xyz="-4e-06 0.0 0.09955"/>
    <axis xyz="0.0 -0.0 1.0"/>
    <limit effort="330.0" lower="-6.283185307179586" upper="6.283185307179586" velocity="2.0943951023931953"/>
    <dynamics damping="0" friction="0"/>
  </joint>
  <joint name="sim_ur10e_shoulder_lift_joint" type="revolute">
    <parent link="sim_ur10e_shoulder_link"/>
    <child link="sim_ur10e_upper_arm_link"/>
    <origin rpy="0 0 0" xyz="0.0 0.086 0.09"/>
    <axis xyz="0.0 1.0 0.0"/>
    <limit effort="330.0" lower="-6.283185307179586" upper="6.283185307179586" velocity="2.0943951023931953"/>
    <dynamics damping="0" friction="0"/>
  </joint>
  <joint name="sim_ur10e_elbow_joint" type="revolute">
    <parent link="sim_ur10e_upper_arm_link"/>
    <child link="sim_ur10e_forearm_link"/>
    <origin rpy="0 0 0" xyz="0.612099 0.021891 -0.000601"/>
    <axis xyz="0.0 1.0 -0.0"/>
    <limit effort="150.0" lower="-3.141592653589793" upper="3.141592653589793" velocity="3.141592653589793"/>
    <dynamics damping="0" friction="0"/>
  </joint>
  <joint name="sim_ur10e_wrist_1_joint" type="revolute">
    <parent link="sim_ur10e_forearm_link"/>
    <child link="sim_ur10e_wrist_1_link"/>
    <origin rpy="0 0 0" xyz="0.571598 0.002 0.0"/>
    <axis xyz="0.0 1.0 0.0"/>
    <limit effort="54.0" lower="-6.283185307179586" upper="6.283185307179586" velocity="3.141592653589793"/>
    <dynamics damping="0" friction="0"/>
  </joint>
  <joint name="sim_ur10e_wrist_2_joint" type="revolute">
    <parent link="sim_ur10e_wrist_1_link"/>
    <child link="sim_ur10e_wrist_2_link"/>
    <origin rpy="0 0 0" xyz="0.0 0.054 -0.061699"/>
    <axis xyz="0.0 0.0 -1.0"/>
    <limit effort="54.0" lower="-6.283185307179586" upper="6.283185307179586" velocity="3.141592653589793"/>
    <dynamics damping="0" friction="0"/>
  </joint>
  <joint name="sim_ur10e_wrist_3_joint" type="revolute">
    <parent link="sim_ur10e_wrist_2_link"/>
    <child link="sim_ur10e_wrist_3_link"/>
    <origin rpy="0 0 0" xyz="0.0 0.061698 -0.054"/>
    <axis xyz="0.0 1.0 0.0"/>
    <limit effort="54.0" lower="-6.283185307179586" upper="6.283185307179586" velocity="3.141592653589793"/>
    <dynamics damping="0" friction="0"/>
  </joint>
  <link name="sim_ur10e_ft_frame"/>
  <joint name="sim_ur10e_wrist_3_link-ft_frame" type="fixed">
    <parent link="sim_ur10e_wrist_3_link"/>
    <child link="sim_ur10e_ft_frame"/>
    <origin rpy="3.141592653589793 0 0" xyz="0 0 0"/>
  </joint>
  <!-- ROS-Industrial 'base' frame - base_link to UR 'Base' Coordinates transform -->
  <link name="sim_ur10e_base"/>
  <joint name="sim_ur10e_base_link-base_fixed_joint" type="fixed">
    <!-- Note the rotation over Z of pi radians - as base_link is REP-103
           aligned (i.e., has X+ forward, Y+ left and Z+ up), this is needed
           to correctly align 'base' with the 'Base' coordinate system of
           the UR controller.
      -->
    <origin rpy="0 0 3.141592653589793" xyz="0 0 0"/>
    <parent link="sim_ur10e_base_link"/>
    <child link="sim_ur10e_base"/>
  </joint>
  <!-- ROS-Industrial 'flange' frame - attachment point for EEF models -->
  <link name="sim_ur10e_flange">
    <inertial>
      <origin rpy="0 0 0" xyz="-0.0608781963738787 0.032615699999237635 0.00948696917434988"/>
      <mass value="0.22117646672683344"/>
      <inertia ixx="0.000146" ixy="3e-05" ixz="2e-06" iyy="0.000196" iyz="0.0" izz="0.000224"/>
    </inertial>
    <visual>
      <origin rpy="0 0 0" xyz="-1.106132 -0.502789 -0.727752"/>
      <geometry>
        <mesh filename="file:////home/cem/colcon_ws/src/Universal_Robots_ROS2_Description/meshes/ur10e/secondrobotcollision/flange.stl" scale="0.001 0.001 0.001"/>
      </geometry>
      <material name="silver"/>
    </visual>
    <collision>
      <origin rpy="0 0 0" xyz="-1.106132 -0.502789 -0.727752"/>
      <geometry>
        <mesh filename="file:////home/cem/colcon_ws/src/Universal_Robots_ROS2_Description/meshes/ur10e/secondrobotcollision/flange.stl" scale="0.001 0.001 0.001"/>
      </geometry>
    </collision>
  </link>
  <joint name="sim_ur10e_wrist_3-tool0" type="fixed">
    <parent link="sim_ur10e_wrist_3_link"/>
    <child link="sim_ur10e_tool0"/>
    <origin rpy="0 0 0" xyz="0.0 0.0605 2e-06"/>
  </joint>
  <!-- ROS-Industrial 'tool0' frame - all-zeros tool frame -->
  <link name="sim_ur10e_tool0">
    <inertial>
      <origin rpy="0 0 0" xyz="0.0005008754706203877 0.038081991894250655 0.00018003251162090894"/>
      <mass value="1.7658241523371878"/>
      <inertia ixx="0.001386" ixy="3e-05" ixz="6e-06" iyy="0.001768" iyz="1e-05" izz="0.002292"/>
    </inertial>
    <visual>
      <origin rpy="0 0 0" xyz="-1.078132 -0.477889 -0.717752"/>
      <geometry>
        <mesh filename="file:////home/cem/colcon_ws/src/Universal_Robots_ROS2_Description/meshes/ur10e/secondrobotcollision/tool0.stl" scale="0.001 0.001 0.001"/>
      </geometry>
      <material name="silver"/>
    </visual>
    <collision>
      <origin rpy="0 0 0" xyz="-1.078132 -0.477889 -0.717752"/>
      <geometry>
        <mesh filename="file:////home/cem/colcon_ws/src/Universal_Robots_ROS2_Description/meshes/ur10e/secondrobotcollision/tool0.stl" scale="0.001 0.001 0.001"/>
      </geometry>
    </collision>
  </link>
  <link name="sim_ur10e_sick_camera">
    <inertial>
      <origin rpy="0 0 0" xyz="-0.030360308070560116 0.017381415318390325 -0.0003625735829336785"/>
      <mass value="2.884207514548234"/>
      <inertia ixx="0.002502" ixy="-0.000172" ixz="-6e-06" iyy="0.002303" iyz="1.7e-05" izz="0.002674"/>
    </inertial>
    <visual>
      <origin rpy="0 0 0" xyz="-1.02433 -0.5466 -0.730752"/>
      <geometry>
        <mesh filename="file:////home/cem/colcon_ws/src/Universal_Robots_ROS2_Description/meshes/ur10e/secondrobotcollision/sick_camera_mo.stl" scale="0.001 0.001 0.001"/>
      </geometry>
      <material name="silver"/>
    </visual>
    <collision>
      <origin rpy="0 0 0" xyz="-1.02433 -0.5466 -0.730752"/>
      <geometry>
        <mesh filename="file:////home/cem/colcon_ws/src/Universal_Robots_ROS2_Description/meshes/ur10e/secondrobotcollision/sick_camera_mo.stl" scale="0.001 0.001 0.001"/>
      </geometry>
    </collision>
  </link>
  <joint name="sim_ur10e_flange-tool0" type="fixed">
    <origin rpy="0 0 0" xyz="0.028 0.0249 0.01"/>
    <parent link="sim_ur10e_tool0"/>
    <child link="sim_ur10e_flange"/>
  </joint>
  <joint name="sim_ur10e_tool0-sickcamera" type="fixed">
    <origin rpy="0 0 0" xyz="-0.081802 0.043811 0.003"/>
    <parent link="sim_ur10e_flange"/>
    <child link="sim_ur10e_sick_camera"/>
  </joint>
  <!-- Gripper links and joints (conditional on use_gripper parameter) -->
  <!-- <xacro:if value="${use_gripper}">
      <xacro:include filename="$(find gripper_test)/urdf/gripper_macro.xacro" />
      <xacro:gripper
        tf_prefix="${tf_prefix}"
        parent="world"
        sim_ignition="${sim_ignition}">
        <origin xyz="3 0 0" rpy="0 0 0"/>
      </xacro:gripper>
    </xacro:if> -->
  <link name="sim_ur10e_gripper_body_1">
    <inertial>
      <origin rpy="0 0 0" xyz="0.046201794305521515 0.04641351769017876 -0.017675503740650633"/>
      <mass value="4.92893092862587"/>
      <inertia ixx="0.006626" ixy="-0.000805" ixz="8e-06" iyy="0.0075" iyz="4e-06" izz="0.005595"/>
    </inertial>
    <visual>
      <origin rpy="0 0 0" xyz="-1.123708 -0.518786 -0.735428"/>
      <geometry>
        <mesh filename="file:////home/cem/colcon_ws/src/Universal_Robots_ROS2_Description/meshes/ur10e/secondrobotcollision/gripper_body_1.stl" scale="0.001 0.001 0.001"/>
      </geometry>
      <material name="violet">
        <color rgba="0.4 0.18 0.57 1.0"/>
      </material>
    </visual>
    <collision>
      <origin rpy="0 0 0" xyz="-1.123708 -0.518786 -0.735428"/>
      <geometry>
        <mesh filename="file:////home/cem/colcon_ws/src/Universal_Robots_ROS2_Description/meshes/ur10e/secondrobotcollision/gripper_body_1.stl" scale="0.001 0.001 0.001"/>
      </geometry>
    </collision>
  </link>
  <link name="sim_ur10e_gripper_upper_1">
    <inertial>
      <origin rpy="0 0 0" xyz="0.009933945618336715 0.020191952923398593 0.002410109555269213"/>
      <mass value="0.15599517357950826"/>
      <inertia ixx="3.7e-05" ixy="-7e-06" ixz="-9e-06" iyy="4.5e-05" iyz="-5e-06" izz="6.6e-05"/>
    </inertial>
    <visual>
      <origin rpy="0 0 0" xyz="-1.22001 -0.579787 -0.7675"/>
      <geometry>
        <mesh filename="file:////home/cem/colcon_ws/src/Universal_Robots_ROS2_Description/meshes/ur10e/secondrobotcollision/gripper_upper_1.stl" scale="0.001 0.001 0.001"/>
      </geometry>
      <material name="grey">
        <color rgba="0.2 0.2 0.2 1.0"/>
      </material>
    </visual>
    <collision>
      <origin rpy="0 0 0" xyz="-1.22001 -0.579787 -0.7675"/>
      <geometry>
        <mesh filename="file:////home/cem/colcon_ws/src/Universal_Robots_ROS2_Description/meshes/ur10e/secondrobotcollision/gripper_upper_1.stl" scale="0.001 0.001 0.001"/>
      </geometry>
    </collision>
  </link>
  <link name="sim_ur10e_gripper_lower_1">
    <inertial>
      <origin rpy="0 0 0" xyz="0.009953097781983722 0.020157371452492412 -0.0024101337743568374"/>
      <mass value="0.15599517357965467"/>
      <inertia ixx="3.7e-05" ixy="-7e-06" ixz="9e-06" iyy="4.5e-05" iyz="5e-06" izz="6.6e-05"/>
    </inertial>
    <visual>
      <origin rpy="0 0 0" xyz="-1.22001 -0.579787 -0.668"/>
      <geometry>
        <mesh filename="file:////home/cem/colcon_ws/src/Universal_Robots_ROS2_Description/meshes/ur10e/secondrobotcollision/gripper_lower_1.stl" scale="0.001 0.001 0.001"/>
      </geometry>
      <material name="grey">
        <color rgba="0.2 0.2 0.2 1.0"/>
      </material>
    </visual>
    <collision>
      <origin rpy="0 0 0" xyz="-1.22001 -0.579787 -0.668"/>
      <geometry>
        <mesh filename="file:////home/cem/colcon_ws/src/Universal_Robots_ROS2_Description/meshes/ur10e/secondrobotcollision/gripper_lower_1.stl" scale="0.001 0.001 0.001"/>
      </geometry>
    </collision>
  </link>
  <joint name="sim_ur10e_gripper_body_joint" type="fixed">
    <origin rpy="0 0 0" xyz="0.045576 0.040897 0.017678"/>
    <parent link="sim_ur10e_tool0"/>
    <child link="sim_ur10e_gripper_body_1"/>
  </joint>
  <joint name="sim_ur10e_gripper_joint" type="prismatic">
    <origin rpy="0 0 0" xyz="0.096302 0.061001 0.032072"/>
    <parent link="sim_ur10e_gripper_body_1"/>
    <child link="sim_ur10e_gripper_upper_1"/>
    <axis xyz="0.0 0.0 -1.0"/>
    <!-- limits extended ±0.001 beyond nominal 0..0.025 range to work around DART servo bug (dartsim/dart#1683) -->
    <limit effort="1000" lower="-0.001" upper="0.026" velocity="10"/>
  </joint>
  <joint name="sim_ur10e_gripper_lower_finger_joint" type="prismatic">
    <origin rpy="0 0 0" xyz="0.096302 0.061001 -0.067428"/>
    <parent link="sim_ur10e_gripper_body_1"/>
    <child link="sim_ur10e_gripper_lower_1"/>
    <axis xyz="0.0 0.0 -1.0"/>
    <mimic joint="sim_ur10e_gripper_joint" multiplier="-1.0"/>
    <!-- limits extended ±0.001 beyond nominal -0.025..0 range to work around DART servo bug (dartsim/dart#1683) -->
    <limit effort="1000" lower="-0.026" upper="0.001" velocity="10"/>
  </joint>
  <link name="sim_ur10e_cable_channel_flange">
    <inertial>
      <origin rpy="0 0 0" xyz="4.611879362848015e-07 -0.034962924750167046 -0.015484781070814413"/>
      <mass value="0.0634433620618905"/>
      <inertia ixx="2.8e-05" ixy="0.0" ixz="0.0" iyy="2.6e-05" iyz="-1e-05" izz="2.3e-05"/>
    </inertial>
    <visual>
      <origin rpy="0 0 0" xyz="-1.078132 -0.537789 -0.707752"/>
      <geometry>
        <mesh filename="file:////home/cem/colcon_ws/src/Universal_Robots_ROS2_Description/meshes/ur10e/secondrobotcollision/cable_channel_flange.stl" scale="0.001 0.001 0.001"/>
      </geometry>
      <material name="silver"/>
    </visual>
    <collision>
      <origin rpy="0 0 0" xyz="-1.078132 -0.537789 -0.707752"/>
      <geometry>
        <mesh filename="file:////home/cem/colcon_ws/src/Universal_Robots_ROS2_Description/meshes/ur10e/secondrobotcollision/cable_channel_flange.stl" scale="0.001 0.001 0.001"/>
      </geometry>
    </collision>
  </link>
  <link name="sim_ur10e_cable_channel">
    <inertial>
      <origin rpy="0 0 0" xyz="-0.0007043985483754511 1.4782874641072752e-07 -0.030869319710005172"/>
      <mass value="0.4154967185204701"/>
      <inertia ixx="0.00017" ixy="-0.0" ixz="6e-06" iyy="0.000341" iyz="-0.0" izz="0.000223"/>
    </inertial>
    <visual>
      <origin rpy="0 0 0" xyz="-1.078132 -0.486789 -0.669752"/>
      <geometry>
        <mesh filename="file:////home/cem/colcon_ws/src/Universal_Robots_ROS2_Description/meshes/ur10e/secondrobotcollision/cable_channel.stl" scale="0.001 0.001 0.001"/>
      </geometry>
      <material name="silver"/>
    </visual>
    <collision>
      <origin rpy="0 0 0" xyz="-1.078132 -0.486789 -0.669752"/>
      <geometry>
        <mesh filename="file:////home/cem/colcon_ws/src/Universal_Robots_ROS2_Description/meshes/ur10e/secondrobotcollision/cable_channel.stl" scale="0.001 0.001 0.001"/>
      </geometry>
    </collision>
  </link>
  <joint name="sim_ur10e_cable_channel_flange-tool0" type="fixed">
    <origin rpy="0 0 0" xyz="0.0 0.0599 -0.01"/>
    <parent link="sim_ur10e_tool0"/>
    <child link="sim_ur10e_cable_channel_flange"/>
  </joint>
  <joint name="sim_ur10e_cable_channel_flange-spiral" type="fixed">
    <origin rpy="0 0 0" xyz="0.0 -0.051 -0.038"/>
    <parent link="sim_ur10e_cable_channel_flange"/>
    <child link="sim_ur10e_cable_channel"/>
  </joint>
  <link name="sim_ur10e_depth_frame"/>
  <link name="sim_ur10e_depth_optical_frame"/>
  <link name="sim_ur10e_rgb_frame"/>
  <link name="sim_ur10e_rgb_optical_frame"/>
  <joint name="sim_ur10e_depth_joint" type="fixed">
    <origin rpy="0 0 0" xyz="0.0 0.02 0.0"/>
    <parent link="sim_ur10e_sick_camera"/>
    <child link="sim_ur10e_depth_frame"/>
  </joint>
  <joint name="sim_ur10e_depth_optical_joint" type="fixed">
    <origin rpy="-1.5707963267948966 -1.5707963267948966 0.0" xyz="0 0 0"/>
    <parent link="sim_ur10e_depth_frame"/>
    <child link="sim_ur10e_depth_optical_frame"/>
  </joint>
  <joint name="sim_ur10e_rgb_joint" type="fixed">
    <origin rpy="0 0 0" xyz="0.0 0.0125 0.0"/>
    <parent link="sim_ur10e_sick_camera"/>
    <child link="sim_ur10e_rgb_frame"/>
  </joint>
  <joint name="sim_ur10e_rgb_optical_joint" type="fixed">
    <origin rpy="-1.5707963267948966 -1.5707963267948966 0.0" xyz="0 0 0"/>
    <parent link="sim_ur10e_rgb_frame"/>
    <child link="sim_ur10e_rgb_optical_frame"/>
  </joint>
  <link name="sim_ur10e_IMX_Camera">
    <inertial>
      <origin rpy="0 0 0" xyz="5.410014880524727e-07 0.008501727362029532 -0.018614321006647505"/>
      <mass value="0.044117104706977495"/>
      <inertia ixx="6e-06" ixy="0.0" ixz="-0.0" iyy="5e-06" iyz="0.0" izz="5e-06"/>
    </inertial>
    <visual>
      <origin rpy="0 0 0" xyz="-1.078132 -0.499789 -0.70475"/>
      <geometry>
        <mesh filename="file:////home/cem/colcon_ws/src/Universal_Robots_ROS2_Description/meshes/ur10e/secondrobotcollision/IMX_Camera.stl" scale="0.001 0.001 0.001"/>
      </geometry>
      <material name="silver"/>
    </visual>
    <collision>
      <origin rpy="0 0 0" xyz="-1.078132 -0.499789 -0.70475"/>
      <geometry>
        <mesh filename="file:////home/cem/colcon_ws/src/Universal_Robots_ROS2_Description/meshes/ur10e/secondrobotcollision/IMX_Camera.stl" scale="0.001 0.001 0.001"/>
      </geometry>
    </collision>
  </link>
  <joint name="sim_ur10e_IMX_Camera_joint" type="fixed">
    <origin rpy="0 0 0" xyz="0.0 -0.038 -0.003"/>
    <parent link="sim_ur10e_cable_channel_flange"/>
    <child link="sim_ur10e_IMX_Camera"/>
  </joint>
  <!-- Sensors system: SADECE 1 KERE -->
  <gazebo>
    <plugin filename="ignition-gazebo-sensors-system" name="ignition::gazebo::systems::Sensors">
      <render_engine>ogre2</render_engine>
    </plugin>
  </gazebo>
  <!-- RGBD camera (depth_optical_frame linkine bağlı) -->
  <gazebo reference="sim_ur10e_depth_optical_frame">
    <sensor name="sim_ur10e_rgbd_camera" type="rgbd_camera">
      <always_on>true</always_on>
      <update_rate>30.0</update_rate>
      <visualize>false</visualize>
      <camera name="sim_ur10e_rgbd">
        <horizontal_fov>1.22</horizontal_fov>
        <image>
          <width>512</width>
          <height>424</height>
          <format>R8G8B8</format>
        </image>
        <depth_image>
          <width>512</width>
          <height>424</height>
          <format>R_FLOAT32</format>
        </depth_image>
        <clip>
          <near>0.05</near>
          <far>16.0</far>
        </clip>
      </camera>
    </sensor>
  </gazebo>
  <!-- IMX179 RGB camera (IMX_Camera linkine bağlı) -->
  <gazebo reference="sim_ur10e_IMX_Camera">
    <sensor name="sim_ur10e_imx179_camera" type="camera">
      <always_on>true</always_on>
      <update_rate>30.0</update_rate>
      <visualize>false</visualize>
      <camera name="sim_ur10e_imx179_rgb">
        <!-- 145 deg = 2.5307 rad -->
        <horizontal_fov>2.5307</horizontal_fov>
        <image>
          <width>3288</width>
          <height>2512</height>
          <format>R8G8B8</format>
        </image>
        <clip>
          <near>0.05</near>
          <far>16.0</far>
        </clip>
      </camera>
    </sensor>
  </gazebo>
  <gazebo>
    <plugin filename="libgz-sim-joint-state-publisher-system.so" name="gz::sim::systems::JointStatePublisher">
      <topic>/sim_robot_joint_states</topic>
    </plugin>
  </gazebo>
  <!-- Inertia helper macros -->
  <property name="M_PI" value="3.1415926535897931"/>
  <!-- see https://secure.wikimedia.org/wikipedia/en/wiki/List_of_moment_of_inertia_tensors -->
  <property name="M_PI" value="3.1415926535897931"/>
  <ros2_control name="ota_system" type="system">
    <hardware>
      <plugin>gz_ros2_control/GazeboSimSystem</plugin>
    </hardware>
    <!-- Right wheel -->
    <joint name="wheel_right_base">
      <command_interface name="velocity"/>
      <state_interface name="position"/>
      <state_interface name="velocity"/>
    </joint>
    <!-- Left wheel -->
    <joint name="wheel_left_base">
      <command_interface name="velocity"/>
      <state_interface name="position"/>
      <state_interface name="velocity"/>
    </joint>
  </ros2_control>
  <link name="ota_base_link">
    <origin rpy=" 0 0 0" xyz="0 0 0"/>
    <visual>
      <origin rpy=" 0 0 0" xyz="-0.1 0 -0.1625"/>
      <geometry>
        <mesh filename="file:////home/cem/colcon_ws/src/mobile_manipulator_description/meshes/ota/OTA-v0.7.stl" scale="0.001 0.001 0.001"/>
      </geometry>
      <material name="DefaultWhite">
        <color rgba="1 1 1 1"/>
      </material>
    </visual>
    <collision>
      <origin rpy=" 0 0 0" xyz="0 0 0.015"/>
      <geometry>
        <box size="1.02605 0.728 0.3"/>
      </geometry>
    </collision>
    <inertial>
      <mass value="50.0"/>
      <origin xyz="0 0 0"/>
      <inertia ixx="2.58326563336" ixy="0.0" ixz="0.0" iyy="4.761575605785662" iyz="0.0" izz="6.594841539145662"/>
    </inertial>
  </link>
  <gazebo reference="ota_base_link">
    <mu1>0.1</mu1>
    <mu2>0.1</mu2>
    <material>Gazebo/Orange</material>
    <visual>
      <material>
        <ambient>0.85 0.35 0 1</ambient>
        <diffuse>0.85 0.35 0 1</diffuse>
        <specular>0.1 0.1 0.1 1</specular>
      </material>
    </visual>
  </gazebo>
  <link name="manipulator_base_link">
    <origin rpy=" 0 0 0" xyz="0 0 0"/>
    <visual>
      <origin rpy=" 0 0 0" xyz="0 0 -0.0"/>
      <geometry>
        <box size="0.187945 0.190701 0.103"/>
      </geometry>
    </visual>
    <collision>
      <origin rpy=" 0 0 0" xyz="0 0 -0.0"/>
      <geometry>
        <box size="0.187945 0.190701 0.103"/>
      </geometry>
    </collision>
    <inertial>
      <mass value="5.0"/>
      <origin xyz="0 0 0"/>
      <inertia ixx="0.01957327192110477" ixy="0.0" ixz="0.0" iyy="0.01913846027169616" iyz="0.0" izz="0.029870902395800928"/>
    </inertial>
  </link>
  <!-- <gazebo reference="manipulator_base_link">
      <material>Gazebo/Orange</material>
      <visual>
        <material>
          <ambient>1 0.5 0 1</ambient>
          <diffuse>1 0.5 0 1</diffuse>
          <specular>0.1 0.1 0.1 1</specular>
        </material>
      </visual>
    </gazebo> -->
  <joint name="base2manipulatorbase" type="fixed">
    <parent link="ota_base_link"/>
    <child link="manipulator_base_link"/>
    <origin rpy="0 0 0" xyz="0.001 -0.26 0.212"/>
  </joint>
  <link name="ota_ir_link">
    <!-- Inertial -->
    <inertial>
      <mass value="0.001"/>
      <origin xyz="0 0 0"/>
      <inertia ixx="0.001666" ixy="0" ixz="0" iyy="0.001666" iyz="0" izz="0.001666"/>
    </inertial>
    <!-- Visual -->
    <visual>
      <origin xyz="0 0 0"/>
      <geometry>
        <box size="0.02 0.02 0.02"/>
      </geometry>
    </visual>
    <!-- Collision -->
    <collision>
      <origin xyz="0 0 0"/>
      <geometry>
        <box size="0.02 0.02 0.02"/>
      </geometry>
    </collision>
    <!-- Gazebo sensor plugin (IR/Range) -->
    <gazebo reference="ota_ir_link">
      <sensor name="ota_ir_sensor" type="ray">
        <always_on>true</always_on>
        <update_rate>20</update_rate>
        <pose>-0.1 0 0 0 0 0</pose>
        <visualize>true</visualize>
      </sensor>
    </gazebo>
  </link>
  <joint name="ota_ir_joint" type="fixed">
    <origin rpy="0 0 0" xyz="0.403 0.0 0.03"/>
    <parent link="ota_base_link"/>
    <child link="ota_ir_link"/>
  </joint>
  <!-- === WHEEL VISUAL === -->
  <link name="wheel_left_link">
    <visual>
      <origin rpy="0 0 1.570796" xyz="0 0 0"/>
      <geometry>
        <mesh filename="file:////home/cem/colcon_ws/src/mobile_manipulator_description/meshes/ota/AnaTeker.stl" scale="0.001 0.001 0.001"/>
      </geometry>
    </visual>
    <!-- === WHEEL COLLISION (simple cylinder) === -->
    <collision>
      <origin rpy="0 1.570796 1.570796" xyz="0 0 0"/>
      <geometry>
        <cylinder length="0.02" radius="0.102"/>
      </geometry>
    </collision>
    <inertial>
      <mass value="5"/>
      <origin xyz="0 0 0"/>
      <inertia ixx="0.013171666666666663" ixy="0.0" ixz="0.0" iyy="0.013171666666666663" iyz="0.0" izz="0.02601"/>
    </inertial>
  </link>
  <!-- === WHEEL JOINT === -->
  <joint name="wheel_left_base" type="continuous">
    <origin rpy="0 0 0" xyz="0 -0.30 -0.06"/>
    <parent link="ota_base_link"/>
    <child link="wheel_left_link"/>
    <axis xyz="0 1 0"/>
  </joint>
  <!-- Gazebo wheel parameters -->
  <gazebo reference="wheel_left_link">
    <mu1>1.0</mu1>
    <mu2>1.0</mu2>
    <kp>1000000.0</kp>
    <kd>10.0</kd>
    <minDepth>0.001</minDepth>
    <material>Gazebo/Red</material>
    <visual>
      <material>
        <ambient>1 0 0 1</ambient>
        <diffuse>1 0 0 1</diffuse>
        <specular>0.1 0.1 0.1 1</specular>
      </material>
    </visual>
  </gazebo>
  <!-- === WHEEL VISUAL === -->
  <link name="wheel_right_link">
    <visual>
      <origin rpy="0 0 1.570796" xyz="0 0 0"/>
      <geometry>
        <mesh filename="file:////home/cem/colcon_ws/src/mobile_manipulator_description/meshes/ota/AnaTeker.stl" scale="0.001 0.001 0.001"/>
      </geometry>
    </visual>
    <!-- === WHEEL COLLISION (simple cylinder) === -->
    <collision>
      <origin rpy="0 1.570796 1.570796" xyz="0 0 0"/>
      <geometry>
        <cylinder length="0.02" radius="0.102"/>
      </geometry>
    </collision>
    <inertial>
      <mass value="5"/>
      <origin xyz="0 0 0"/>
      <inertia ixx="0.013171666666666663" ixy="0.0" ixz="0.0" iyy="0.013171666666666663" iyz="0.0" izz="0.02601"/>
    </inertial>
  </link>
  <!-- === WHEEL JOINT === -->
  <joint name="wheel_right_base" type="continuous">
    <origin rpy="0 0 0" xyz="0 0.30 -0.06"/>
    <parent link="ota_base_link"/>
    <child link="wheel_right_link"/>
    <axis xyz="0 1 0"/>
  </joint>
  <!-- Gazebo wheel parameters -->
  <gazebo reference="wheel_right_link">
    <mu1>1.0</mu1>
    <mu2>1.0</mu2>
    <kp>1000000.0</kp>
    <kd>10.0</kd>
    <minDepth>0.001</minDepth>
    <material>Gazebo/Red</material>
    <visual>
      <material>
        <ambient>1 0 0 1</ambient>
        <diffuse>1 0 0 1</diffuse>
        <specular>0.1 0.1 0.1 1</specular>
      </material>
    </visual>
  </gazebo>
  <!-- CASTER BODY -->
  <link name="caster_front_right_link">
    <visual>
      <origin xyz="0 0 0"/>
      <geometry>
        <mesh filename="file:////home/cem/colcon_ws/src/mobile_manipulator_description/meshes/ota/SarhosTeker.stl" scale="0.001 0.0008 0.001"/>
      </geometry>
    </visual>
    <collision>
      <origin xyz="0 0 0"/>
      <geometry>
        <cylinder length="0.05" radius="0.005"/>
      </geometry>
    </collision>
    <inertial>
      <mass value="1"/>
      <origin xyz="0 0 0"/>
      <inertia ixx="0.0004145833333333334" ixy="0.0" ixz="0.0" iyy="0.0004145833333333334" iyz="0.0" izz="1.25e-05"/>
    </inertial>
  </link>
  <joint name="caster_front_right_joint" type="fixed">
    <axis xyz="0 0 1"/>
    <origin rpy="0 0 0" xyz="0.37 -0.22 -0.048"/>
    <child link="caster_front_right_link"/>
    <parent link="ota_base_link"/>
  </joint>
  <gazebo reference="caster_front_right_link">
    <mu1>1.0</mu1>
    <mu2>1.0</mu2>
    <kp>1000000.0</kp>
    <kd>10.0</kd>
    <minDepth>0.001</minDepth>
    <material>Gazebo/Red</material>
    <visual>
      <material>
        <ambient>1 0 0 1</ambient>
        <diffuse>1 0 0 1</diffuse>
        <specular>0.1 0.1 0.1 1</specular>
      </material>
    </visual>
  </gazebo>
  <!-- <link name='caster_wheel_${side}_link'>
      <visual>
        <origin xyz="0 0 0"/>
        <geometry>
          <cylinder radius="0.042" length="0.02"/>
        </geometry>
      </visual>

      <collision>
        <origin xyz="0 0 0"/>
        <geometry>
          <cylinder radius="0.042" length="0.02"/>
        </geometry>
      </collision>

      <xacro:cylinder_inertial radius="0.042" length="0.02" mass="0.1" />
    </link>      
    
    <joint name="caster_${side}_wheel_joint" type="fixed">
      <axis xyz="0 1 0"/>
      <origin xyz="-0.04 0 -0.07"/>
      <parent link="caster_${side}_link"/>
      <child link="caster_wheel_${side}_link"/>
    </joint>   -->
  <!-- CASTER BODY -->
  <link name="caster_front_left_link">
    <visual>
      <origin xyz="0 0 0"/>
      <geometry>
        <mesh filename="file:////home/cem/colcon_ws/src/mobile_manipulator_description/meshes/ota/SarhosTeker.stl" scale="0.001 0.0008 0.001"/>
      </geometry>
    </visual>
    <collision>
      <origin xyz="0 0 0"/>
      <geometry>
        <cylinder length="0.05" radius="0.005"/>
      </geometry>
    </collision>
    <inertial>
      <mass value="1"/>
      <origin xyz="0 0 0"/>
      <inertia ixx="0.0004145833333333334" ixy="0.0" ixz="0.0" iyy="0.0004145833333333334" iyz="0.0" izz="1.25e-05"/>
    </inertial>
  </link>
  <joint name="caster_front_left_joint" type="fixed">
    <axis xyz="0 0 1"/>
    <origin rpy="0 0 0" xyz="0.37 0.22 -0.048"/>
    <child link="caster_front_left_link"/>
    <parent link="ota_base_link"/>
  </joint>
  <gazebo reference="caster_front_left_link">
    <mu1>1.0</mu1>
    <mu2>1.0</mu2>
    <kp>1000000.0</kp>
    <kd>10.0</kd>
    <minDepth>0.001</minDepth>
    <material>Gazebo/Red</material>
    <visual>
      <material>
        <ambient>1 0 0 1</ambient>
        <diffuse>1 0 0 1</diffuse>
        <specular>0.1 0.1 0.1 1</specular>
      </material>
    </visual>
  </gazebo>
  <!-- <link name='caster_wheel_${side}_link'>
      <visual>
        <origin xyz="0 0 0"/>
        <geometry>
          <cylinder radius="0.042" length="0.02"/>
        </geometry>
      </visual>

      <collision>
        <origin xyz="0 0 0"/>
        <geometry>
          <cylinder radius="0.042" length="0.02"/>
        </geometry>
      </collision>

      <xacro:cylinder_inertial radius="0.042" length="0.02" mass="0.1" />
    </link>      
    
    <joint name="caster_${side}_wheel_joint" type="fixed">
      <axis xyz="0 1 0"/>
      <origin xyz="-0.04 0 -0.07"/>
      <parent link="caster_${side}_link"/>
      <child link="caster_wheel_${side}_link"/>
    </joint>   -->
  <!-- CASTER BODY -->
  <link name="caster_back_right_link">
    <visual>
      <origin xyz="0 0 0"/>
      <geometry>
        <mesh filename="file:////home/cem/colcon_ws/src/mobile_manipulator_description/meshes/ota/SarhosTeker.stl" scale="0.001 0.0008 0.001"/>
      </geometry>
    </visual>
    <collision>
      <origin xyz="0 0 0"/>
      <geometry>
        <cylinder length="0.05" radius="0.005"/>
      </geometry>
    </collision>
    <inertial>
      <mass value="1"/>
      <origin xyz="0 0 0"/>
      <inertia ixx="0.0004145833333333334" ixy="0.0" ixz="0.0" iyy="0.0004145833333333334" iyz="0.0" izz="1.25e-05"/>
    </inertial>
  </link>
  <joint name="caster_back_right_joint" type="fixed">
    <axis xyz="0 0 1"/>
    <origin rpy="0 0 0" xyz="-0.37 -0.22 -0.048"/>
    <child link="caster_back_right_link"/>
    <parent link="ota_base_link"/>
  </joint>
  <gazebo reference="caster_back_right_link">
    <mu1>1.0</mu1>
    <mu2>1.0</mu2>
    <kp>1000000.0</kp>
    <kd>10.0</kd>
    <minDepth>0.001</minDepth>
    <material>Gazebo/Red</material>
    <visual>
      <material>
        <ambient>1 0 0 1</ambient>
        <diffuse>1 0 0 1</diffuse>
        <specular>0.1 0.1 0.1 1</specular>
      </material>
    </visual>
  </gazebo>
  <!-- <link name='caster_wheel_${side}_link'>
      <visual>
        <origin xyz="0 0 0"/>
        <geometry>
          <cylinder radius="0.042" length="0.02"/>
        </geometry>
      </visual>

      <collision>
        <origin xyz="0 0 0"/>
        <geometry>
          <cylinder radius="0.042" length="0.02"/>
        </geometry>
      </collision>

      <xacro:cylinder_inertial radius="0.042" length="0.02" mass="0.1" />
    </link>      
    
    <joint name="caster_${side}_wheel_joint" type="fixed">
      <axis xyz="0 1 0"/>
      <origin xyz="-0.04 0 -0.07"/>
      <parent link="caster_${side}_link"/>
      <child link="caster_wheel_${side}_link"/>
    </joint>   -->
  <!-- CASTER BODY -->
  <link name="caster_back_left_link">
    <visual>
      <origin xyz="0 0 0"/>
      <geometry>
        <mesh filename="file:////home/cem/colcon_ws/src/mobile_manipulator_description/meshes/ota/SarhosTeker.stl" scale="0.001 0.0008 0.001"/>
      </geometry>
    </visual>
    <collision>
      <origin xyz="0 0 0"/>
      <geometry>
        <cylinder length="0.05" radius="0.005"/>
      </geometry>
    </collision>
    <inertial>
      <mass value="1"/>
      <origin xyz="0 0 0"/>
      <inertia ixx="0.0004145833333333334" ixy="0.0" ixz="0.0" iyy="0.0004145833333333334" iyz="0.0" izz="1.25e-05"/>
    </inertial>
  </link>
  <joint name="caster_back_left_joint" type="fixed">
    <axis xyz="0 0 1"/>
    <origin rpy="0 0 0" xyz="-0.37 0.22 -0.048"/>
    <child link="caster_back_left_link"/>
    <parent link="ota_base_link"/>
  </joint>
  <gazebo reference="caster_back_left_link">
    <mu1>1.0</mu1>
    <mu2>1.0</mu2>
    <kp>1000000.0</kp>
    <kd>10.0</kd>
    <minDepth>0.001</minDepth>
    <material>Gazebo/Red</material>
    <visual>
      <material>
        <ambient>1 0 0 1</ambient>
        <diffuse>1 0 0 1</diffuse>
        <specular>0.1 0.1 0.1 1</specular>
      </material>
    </visual>
  </gazebo>
  <!-- <link name='caster_wheel_${side}_link'>
      <visual>
        <origin xyz="0 0 0"/>
        <geometry>
          <cylinder radius="0.042" length="0.02"/>
        </geometry>
      </visual>

      <collision>
        <origin xyz="0 0 0"/>
        <geometry>
          <cylinder radius="0.042" length="0.02"/>
        </geometry>
      </collision>

      <xacro:cylinder_inertial radius="0.042" length="0.02" mass="0.1" />
    </link>      
    
    <joint name="caster_${side}_wheel_joint" type="fixed">
      <axis xyz="0 1 0"/>
      <origin xyz="-0.04 0 -0.07"/>
      <parent link="caster_${side}_link"/>
      <child link="caster_wheel_${side}_link"/>
    </joint>   -->
  <!-- <xacro:ota_ir base_link="${base_link}" link_name="ota_ir" xyz_ir="0.503 0.0 0.175" rpy_ir="0 0 0"/>

    
    <xacro:ota_wheel base_link="${base_link}" xyz_hub="0 -0.305 0.10" rpy_hub="0 0 0" side="left"/>
    <xacro:ota_wheel base_link="${base_link}" xyz_hub="0 0.295 0.10" rpy_hub="0 0 0" side="right"/>

    
    <xacro:ota_swivel base_link="${base_link}" xyz_caster="0.37 -0.223 0.12" rpy_caster="0 0 0" side="front_right"/>
    <xacro:ota_swivel base_link="${base_link}" xyz_caster="0.37 0.217 0.12" rpy_caster="0 0 0" side="front_left"/>
    <xacro:ota_swivel base_link="${base_link}" xyz_caster="-0.37 -0.223 0.12" rpy_caster="0 0 0" side="back_right"/>
    <xacro:ota_swivel base_link="${base_link}" xyz_caster="-0.37 0.217 0.12" rpy_caster="0 0 0" side="back_left"/> -->
  <gazebo>
    <plugin filename="libignition-gazebo6-diff-drive-system.so" name="ignition::gazebo::systems::DiffDrive">
      <!-- Tekerlek eklemleri (ota_wheel.xacro'daki joint isimleri) -->
      <left_joint>wheel_left_base</left_joint>
      <right_joint>wheel_right_base</right_joint>
      <!-- Geometri -->
      <wheel_separation>0.60</wheel_separation>
      <wheel_radius>0.102</wheel_radius>
      <!-- Hız limitleri -->
      <max_linear_acceleration>1.0</max_linear_acceleration>
      <min_linear_acceleration>-1.0</min_linear_acceleration>
      <max_angular_acceleration>2.0</max_angular_acceleration>
      <min_angular_acceleration>-2.0</min_angular_acceleration>
      <!-- Komut ve odom topic'leri - basit isimler (bridge ile ROS'a bağlanacak) -->
      <topic>cmd_vel</topic>
      <odom_topic>odom</odom_topic>
      <!-- TF yayınla -->
      <odom_publish_frequency>50</odom_publish_frequency>
      <tf_topic>/tf</tf_topic>
      <!-- Frame isimleri: odom -> ota_base_link (world->odom static TF ile ayarlanacak) -->
      <frame_id>odom</frame_id>
      <child_frame_id>ota_base_link</child_frame_id>
    </plugin>
  </gazebo>
  <gazebo>
    <plugin filename="libignition-gazebo6-joint-state-publisher-system.so" name="ignition::gazebo::systems::JointStatePublisher">
      <update_rate>50</update_rate>
    </plugin>
  </gazebo>
  <ros2_control name="rs005l" type="system">
    <hardware>
      <plugin>gz_ros2_control/GazeboSimSystem</plugin>
    </hardware>
    <!-- orjinalinde command interface effort bunu sormak lazım -->
    <joint name="joint1">
      <command_interface name="position"/>
      <state_interface name="position"/>
      <state_interface name="velocity"/>
    </joint>
    <joint name="joint2">
      <command_interface name="position"/>
      <state_interface name="position"/>
      <state_interface name="velocity"/>
    </joint>
    <joint name="joint3">
      <command_interface name="position"/>
      <state_interface name="position"/>
      <state_interface name="velocity"/>
    </joint>
    <joint name="joint4">
      <command_interface name="position"/>
      <state_interface name="position"/>
      <state_interface name="velocity"/>
    </joint>
    <joint name="joint5">
      <command_interface name="position"/>
      <state_interface name="position"/>
      <state_interface name="velocity"/>
    </joint>
    <joint name="joint6">
      <command_interface name="position"/>
      <state_interface name="position"/>
      <state_interface name="velocity"/>
    </joint>
  </ros2_control>
  <!--
    ROS1: Bu dosya ros_control transmission tanımlarını içeriyordu.

    ROS2 Humble + Ignition:
      - "transmission_interface/SimpleTransmission" artık kullanılmıyor.
      - Joint command interface'leri ros2_control üzerinden tanımlanacak.
      - Simülasyon tarafı gz_ros2_control plugin ile world/launch içinde kurulacak.

    Bu nedenle bu xacro dosyası ROS2 versiyonunda intentionally no-op'tur.
  -->
  <!-- ROS2 Humble + Ignition:
       Gazebo Classic pluginleri artık çalışmaz.
       ros2_control, gz_ros2_control ve benzeri sistem pluginleri
       world veya launch dosyasında tanımlanmalıdır.
       Bu dosya artık intentionally no-op'tur. -->
  <!-- link rviz colors -->
  <material name="White">
    <color rgba="1 1 1 1"/>
  </material>
  <material name="Black">
    <color rgba="0 0 0 1"/>
  </material>
  <material name="silver">
    <color rgba="0.7 0.7 0.7 1.0"/>
  </material>
  <!-- === Link 0 === -->
  <link name="base_link">
    <visual>
      <geometry>
        <mesh filename="package://mobile_manipulator_description/meshes/khi_rs/RS005L_J0.STL"/>
      </geometry>
      <material name="White"/>
      <origin rpy="0 0 0" xyz="0 0 0"/>
    </visual>
    <collision>
      <geometry>
        <mesh filename="package://mobile_manipulator_description/meshes/khi_rs/RS005L_J0.STL"/>
      </geometry>
      <material name="White"/>
      <origin rpy="0 0 0" xyz="0 0 0"/>
    </collision>
    <inertial>
      <mass value="5.91"/>
      <inertia ixx="1.0" ixy="0.0" ixz="0.0" iyy="1.0" iyz="0.0" izz="1.0"/>
    </inertial>
  </link>
  <joint name="base_mount" type="fixed">
    <parent link="manipulator_base_link"/>
    <child link="base_link"/>
    <origin rpy="0 0 3.141593" xyz="0 0 0.051"/>
  </joint>
  <link name="link1">
    <visual>
      <geometry>
        <mesh filename="package://mobile_manipulator_description/meshes/khi_rs/RS005L_J1.STL"/>
      </geometry>
      <material name="White"/>
      <origin rpy="0 0 0" xyz="0 0 0"/>
    </visual>
    <collision>
      <geometry>
        <mesh filename="package://mobile_manipulator_description/meshes/khi_rs/RS005L_J1.STL"/>
      </geometry>
      <material name="White"/>
      <origin rpy="0 0 0" xyz="0 0 0"/>
    </collision>
    <inertial>
      <mass value="10.395"/>
      <inertia ixx="1.0" ixy="0.0" ixz="0.0" iyy="1.0" iyz="0.0" izz="1.0"/>
    </inertial>
  </link>
  <link name="link2">
    <visual>
      <geometry>
        <mesh filename="package://mobile_manipulator_description/meshes/khi_rs/RS005L_J2.STL"/>
      </geometry>
      <material name="White"/>
      <origin rpy="0 0 0" xyz="0 0 0"/>
    </visual>
    <collision>
      <geometry>
        <mesh filename="package://mobile_manipulator_description/meshes/khi_rs/RS005L_J2.STL"/>
      </geometry>
      <material name="White"/>
      <origin rpy="0 0 0" xyz="0 0 0"/>
    </collision>
    <inertial>
      <mass value="8.788"/>
      <inertia ixx="1.0" ixy="0.0" ixz="0.0" iyy="1.0" iyz="0.0" izz="1.0"/>
    </inertial>
  </link>
  <link name="link3">
    <visual>
      <geometry>
        <mesh filename="package://mobile_manipulator_description/meshes/khi_rs/RS005L_J3.STL"/>
      </geometry>
      <material name="White"/>
      <origin rpy="0 0 0" xyz="0 0 0"/>
    </visual>
    <collision>
      <geometry>
        <mesh filename="package://mobile_manipulator_description/meshes/khi_rs/RS005L_J3.STL"/>
      </geometry>
      <material name="White"/>
      <origin rpy="0 0 0" xyz="0 0 0"/>
    </collision>
    <inertial>
      <mass value="7.575"/>
      <inertia ixx="1.0" ixy="0.0" ixz="0.0" iyy="1.0" iyz="0.0" izz="1.0"/>
    </inertial>
  </link>
  <link name="link4">
    <visual>
      <geometry>
        <mesh filename="package://mobile_manipulator_description/meshes/khi_rs/RS005L_J4.STL"/>
      </geometry>
      <material name="White"/>
      <origin rpy="0 0 0" xyz="0 0 0"/>
    </visual>
    <collision>
      <geometry>
        <mesh filename="package://mobile_manipulator_description/meshes/khi_rs/RS005L_J4.STL"/>
      </geometry>
      <material name="White"/>
      <origin rpy="0 0 0" xyz="0 0 0"/>
    </collision>
    <inertial>
      <mass value="2.679"/>
      <inertia ixx="1.0" ixy="0.0" ixz="0.0" iyy="1.0" iyz="0.0" izz="1.0"/>
    </inertial>
  </link>
  <link name="link5">
    <visual>
      <geometry>
        <mesh filename="package://mobile_manipulator_description/meshes/khi_rs/RS005L_J5.STL"/>
      </geometry>
      <material name="White"/>
      <origin rpy="0 0 0" xyz="0 0 0"/>
    </visual>
    <collision>
      <geometry>
        <mesh filename="package://mobile_manipulator_description/meshes/khi_rs/RS005L_J5.STL"/>
      </geometry>
      <material name="White"/>
      <origin rpy="0 0 0" xyz="0 0 0"/>
    </collision>
    <inertial>
      <mass value="1.028"/>
      <inertia ixx="1.0" ixy="0.0" ixz="0.0" iyy="1.0" iyz="0.0" izz="1.0"/>
    </inertial>
  </link>
  <link name="link6">
    <visual>
      <geometry>
        <mesh filename="package://mobile_manipulator_description/meshes/khi_rs/RS005L_J6.STL"/>
      </geometry>
      <material name="Black"/>
      <origin rpy="0 0 0" xyz="0 0 0"/>
    </visual>
    <collision>
      <geometry>
        <mesh filename="package://mobile_manipulator_description/meshes/khi_rs/RS005L_J6.STL"/>
      </geometry>
      <material name="Black"/>
      <origin rpy="0 0 0" xyz="0 0 0"/>
    </collision>
    <inertial>
      <mass value="0.625"/>
      <inertia ixx="1.0" ixy="0.0" ixz="0.0" iyy="1.0" iyz="0.0" izz="1.0"/>
    </inertial>
  </link>
  <!-- === Link 1 === -->
  <joint name="joint1" type="revolute">
    <axis rpy="0 0 0" xyz="0 0 -1"/>
    <limit effort="1000.0" lower="-3.141592653589793" upper="3.141592653589793" velocity="5.235987755982989"/>
    <origin rpy="0 0 0" xyz="0 0 0.295"/>
    <parent link="base_link"/>
    <child link="link1"/>
    <dynamics damping="0.0" friction="0.0"/>
  </joint>
  <!-- === Link 2 === -->
  <joint name="joint2" type="revolute">
    <axis rpy="0 0 0" xyz="0 0 1"/>
    <limit effort="1000.0" lower="-1.3962634015954636" upper="2.356194490192345" velocity="5.235987755982989"/>
    <origin rpy="0 -1.5707963267948966 0" xyz="0 0.105 0"/>
    <parent link="link1"/>
    <child link="link2"/>
    <dynamics damping="0.0" friction="0.0"/>
  </joint>
  <!-- === Link 3 === -->
  <joint name="joint3" type="revolute">
    <axis rpy="0 0 0" xyz="0 0 -1"/>
    <limit effort="1000.0" lower="-3.001966313430247" upper="2.059488517353309" velocity="5.235987755982989"/>
    <origin rpy="0 0 0" xyz="0.38 0 0"/>
    <parent link="link2"/>
    <child link="link3"/>
    <dynamics damping="0.0" friction="0.0"/>
  </joint>
  <!-- === Link 4 === -->
  <joint name="joint4" type="revolute">
    <axis rpy="0 0 0" xyz="0 0 1"/>
    <limit effort="1000.0" lower="-6.283185307179586" upper="6.283185307179586" velocity="8.028514559173916"/>
    <origin rpy="0 1.5707963267948966 0" xyz="0.15 -0.08 0"/>
    <parent link="link3"/>
    <child link="link4"/>
    <dynamics damping="0.0" friction="0.0"/>
  </joint>
  <!-- === Link 5 === -->
  <joint name="joint5" type="revolute">
    <axis rpy="0 0 0" xyz="0 0 -1"/>
    <limit effort="1000.0" lower="-2.530727415391778" upper="2.530727415391778" velocity="8.028514559173916"/>
    <origin rpy="0 -1.5707963267948966 0" xyz="0 0 0.26"/>
    <parent link="link4"/>
    <child link="link5"/>
    <dynamics damping="0.0" friction="0.0"/>
  </joint>
  <!-- === Link 6 === -->
  <joint name="joint6" type="revolute">
    <axis rpy="0 0 0" xyz="0 0 1"/>
    <limit effort="1000.0" lower="-6.283185307179586" upper="6.283185307179586" velocity="12.915436464758038"/>
    <origin rpy="0 1.5707963267948966 0" xyz="0.078 0 0"/>
    <parent link="link5"/>
    <child link="link6"/>
    <dynamics damping="0.0" friction="0.0"/>
  </joint>
  <!-- ÇEVRESEL BİLEŞENLER -->
  <gazebo reference="world">
    </gazebo>
  <!-- Unified ros2_control Plugin -->
  <gazebo>
    <plugin filename="gz_ros2_control-system" name="gz_ros2_control::GazeboSimROS2ControlPlugin">
      <parameters></parameters>
      <controller_manager_node_name>controller_manager</controller_manager_node_name>
    </plugin>
  </gazebo>
  <gazebo>
    <plugin filename="libignition-gazebo6-diff-drive-system.so" name="ignition::gazebo::systems::DiffDrive">
      <!-- Tekerlek eklemleri (ota_wheel.xacro'daki joint isimleri) -->
      <left_joint>wheel_left_base</left_joint>
      <right_joint>wheel_right_base</right_joint>
      <!-- Geometri -->
      <wheel_separation>0.60</wheel_separation>
      <wheel_radius>0.102</wheel_radius>
      <!-- Hız limitleri -->
      <max_linear_acceleration>1.0</max_linear_acceleration>
      <min_linear_acceleration>-1.0</min_linear_acceleration>
      <max_angular_acceleration>2.0</max_angular_acceleration>
      <min_angular_acceleration>-2.0</min_angular_acceleration>
      <!-- Komut ve odom topic'leri - basit isimler (bridge ile ROS'a bağlanacak) -->
      <topic>cmd_vel</topic>
      <odom_topic>odom</odom_topic>
      <!-- TF yayınla -->
      <odom_publish_frequency>50</odom_publish_frequency>
      <tf_topic>/tf</tf_topic>
      <!-- Frame isimleri: odom -> ota_base_link (world->odom static TF ile ayarlanacak) -->
      <frame_id>odom</frame_id>
      <child_frame_id>ota_base_link</child_frame_id>
    </plugin>
  </gazebo>
  <gazebo>
    <plugin filename="libignition-gazebo6-joint-state-publisher-system.so" name="ignition::gazebo::systems::JointStatePublisher">
      <update_rate>50</update_rate>
    </plugin>
  </gazebo>
</robot>
